2025-03-12 05:00:59,321 - INFO - 🔧 Backend Flask iniciado.
2025-03-12 05:01:01,382 - INFO - 🔧 Backend Flask iniciado.
2025-03-12 05:01:03,123 - INFO - 🔧 Backend Flask iniciado.
2025-03-12 05:01:04,907 - INFO - 🔧 Backend Flask iniciado.
2025-03-12 05:01:07,060 - INFO - 🔧 Backend Flask iniciado.
2025-03-12 05:01:09,431 - INFO - 🔧 Backend Flask iniciado.
2025-03-12 05:01:11,427 - INFO - 🔧 Backend Flask iniciado.
2025-03-12 05:01:13,189 - INFO - 🔧 Backend Flask iniciado.
2025-03-12 05:01:15,114 - INFO - 🔧 Backend Flask iniciado.
2025-03-12 05:01:16,875 - INFO - 🔧 Backend Flask iniciado.
2025-03-12 05:19:23,702 - INFO - 🔧 Backend Flask iniciado.
2025-03-12 05:31:33,791 - INFO - 🔧 Backend Flask iniciado.
2025-03-12 16:33:26,259 - DEBUG - Intento de inicio de sesión: admin@shelly.local
2025-03-12 16:33:26,276 - DEBUG - Usuario encontrado en la base de datos
2025-03-12 16:33:26,615 - DEBUG - Contraseña correcta
2025-03-12 16:37:46,572 - INFO - 🔧 Backend Flask iniciado.
2025-03-12 16:37:48,370 - INFO - 🔧 Backend Flask iniciado.
2025-03-12 16:37:50,107 - INFO - 🔧 Backend Flask iniciado.
2025-03-12 16:37:51,860 - INFO - 🔧 Backend Flask iniciado.
2025-03-12 16:37:53,602 - INFO - 🔧 Backend Flask iniciado.
2025-03-12 16:41:04,940 - INFO - 🔧 Backend Flask iniciado.
2025-03-12 16:41:06,903 - INFO - 🔧 Backend Flask iniciado.
2025-03-12 16:41:08,879 - INFO - 🔧 Backend Flask iniciado.
2025-03-12 16:41:10,709 - INFO - 🔧 Backend Flask iniciado.
2025-03-12 16:41:12,636 - INFO - 🔧 Backend Flask iniciado.
2025-03-12 16:41:20,557 - INFO - 🔧 Backend Flask iniciado.
2025-03-12 16:41:22,434 - INFO - 🔧 Backend Flask iniciado.
2025-03-12 16:41:24,401 - INFO - 🔧 Backend Flask iniciado.
2025-03-12 16:41:26,126 - INFO - 🔧 Backend Flask iniciado.
2025-03-12 16:41:27,923 - INFO - 🔧 Backend Flask iniciado.
2025-03-12 17:19:25,049 - INFO - 🔧 Backend Flask iniciado.
2025-03-12 17:19:26,870 - INFO - 🔧 Backend Flask iniciado.
2025-03-12 17:19:28,618 - INFO - 🔧 Backend Flask iniciado.
2025-03-12 17:19:30,371 - INFO - 🔧 Backend Flask iniciado.
2025-03-12 17:19:32,099 - INFO - 🔧 Backend Flask iniciado.
2025-03-12 17:41:01,666 - INFO - 🔧 Backend Flask iniciado.
2025-03-12 17:43:21,739 - DEBUG - Intento de inicio de sesión: admin@shelly.local
2025-03-12 17:43:21,749 - DEBUG - Usuario encontrado en la base de datos
2025-03-12 17:43:22,089 - DEBUG - Contraseña correcta
2025-03-12 17:57:57,350 - DEBUG - Intento de inicio de sesión: admin@shelly.local
2025-03-12 17:57:57,352 - DEBUG - Usuario encontrado en la base de datos
2025-03-12 17:57:57,692 - DEBUG - Contraseña correcta
2025-03-12 17:58:50,168 - DEBUG - Intento de inicio de sesión: admin@shelly.local
2025-03-12 17:58:50,170 - DEBUG - Usuario encontrado en la base de datos
2025-03-12 17:58:50,510 - DEBUG - Contraseña correcta
2025-03-12 17:59:31,957 - DEBUG - Intento de inicio de sesión: admin@shelly.local
2025-03-12 17:59:31,959 - DEBUG - Usuario encontrado en la base de datos
2025-03-12 17:59:32,299 - DEBUG - Contraseña correcta
2025-03-12 18:14:34,738 - DEBUG - Intento de inicio de sesión: admin@shelly.local
2025-03-12 18:14:34,745 - DEBUG - Usuario encontrado en la base de datos
2025-03-12 18:14:35,085 - DEBUG - Contraseña correcta
2025-03-12 18:24:40,081 - DEBUG - Intento de inicio de sesión: admin@shelly.local
2025-03-12 18:24:40,085 - DEBUG - Usuario encontrado en la base de datos
2025-03-12 18:24:40,424 - DEBUG - Contraseña correcta
2025-03-12 18:26:27,142 - DEBUG - Intento de inicio de sesión: admin@shelly.local
2025-03-12 18:26:27,144 - DEBUG - Usuario encontrado en la base de datos
2025-03-12 18:26:27,484 - DEBUG - Contraseña correcta
2025-03-12 18:26:51,178 - DEBUG - Intento de inicio de sesión: admin@shelly.local
2025-03-12 18:26:51,180 - DEBUG - Usuario encontrado en la base de datos
2025-03-12 18:26:51,520 - DEBUG - Contraseña correcta
2025-03-12 18:49:38,188 - DEBUG - Intento de inicio de sesión: admin@shelly.local
2025-03-12 18:49:38,190 - DEBUG - Usuario encontrado en la base de datos
2025-03-12 18:49:38,529 - DEBUG - Contraseña correcta
2025-03-12 18:50:52,630 - DEBUG - Intento de inicio de sesión: admin@shelly.local
2025-03-12 18:50:52,632 - DEBUG - Usuario encontrado en la base de datos
2025-03-12 18:50:52,972 - DEBUG - Contraseña correcta
2025-03-12 18:57:41,084 - DEBUG - Intento de inicio de sesión: admin@shelly.local
2025-03-12 18:57:41,087 - DEBUG - Usuario encontrado en la base de datos
2025-03-12 18:57:41,427 - DEBUG - Contraseña correcta
2025-03-12 19:02:46,424 - DEBUG - Intento de inicio de sesión: admin@shelly.local
2025-03-12 19:02:46,427 - DEBUG - Usuario encontrado en la base de datos
2025-03-12 19:02:46,766 - DEBUG - Contraseña correcta
2025-03-12 19:04:22,989 - DEBUG - Intento de inicio de sesión: admin@shelly.local
2025-03-12 19:04:22,992 - DEBUG - Usuario encontrado en la base de datos
2025-03-12 19:04:23,332 - DEBUG - Contraseña correcta
2025-03-12 19:12:04,158 - DEBUG - Intento de inicio de sesión: admin@shelly.local
2025-03-12 19:12:04,160 - DEBUG - Usuario encontrado en la base de datos
2025-03-12 19:12:04,500 - DEBUG - Contraseña correcta
2025-03-12 19:26:40,728 - DEBUG - Intento de inicio de sesión: admin@shelly.local
2025-03-12 19:26:40,735 - DEBUG - Usuario encontrado en la base de datos
2025-03-12 19:26:41,075 - DEBUG - Contraseña correcta
2025-03-12 20:59:17,944 - INFO - 🔧 Backend Flask iniciado.
2025-03-12 20:59:39,695 - DEBUG - Intento de inicio de sesión: admin@shelly.local
2025-03-12 20:59:39,705 - DEBUG - Usuario encontrado en la base de datos
2025-03-12 20:59:40,053 - DEBUG - Contraseña correcta
2025-03-12 21:06:36,159 - DEBUG - Intento de inicio de sesión: admin@shelly.local
2025-03-12 21:06:36,167 - DEBUG - Usuario encontrado en la base de datos
2025-03-12 21:06:36,517 - DEBUG - Contraseña correcta
2025-03-12 21:12:05,669 - INFO - 🔧 Backend Flask iniciado.
2025-03-12 21:12:22,812 - DEBUG - Intento de inicio de sesión: admin@shelly.local
2025-03-12 21:12:22,824 - DEBUG - Usuario encontrado en la base de datos
2025-03-12 21:12:23,161 - DEBUG - Contraseña correcta
2025-03-12 21:19:20,857 - DEBUG - Intento de inicio de sesión: admin@shelly.local
2025-03-12 21:19:20,862 - DEBUG - Usuario encontrado en la base de datos
2025-03-12 21:19:21,202 - DEBUG - Contraseña correcta
2025-03-12 21:21:03,752 - DEBUG - Intento de inicio de sesión: admin@shelly.local
2025-03-12 21:21:03,755 - DEBUG - Usuario encontrado en la base de datos
2025-03-12 21:21:04,095 - DEBUG - Contraseña correcta
2025-03-12 21:32:11,643 - DEBUG - Intento de inicio de sesión: admin@shelly.local
2025-03-12 21:32:11,649 - DEBUG - Usuario encontrado en la base de datos
2025-03-12 21:32:11,989 - DEBUG - Contraseña correcta
2025-03-12 21:40:33,023 - DEBUG - Intento de inicio de sesión: admin@shelly.local
2025-03-12 21:40:33,030 - DEBUG - Usuario encontrado en la base de datos
2025-03-12 21:40:33,370 - DEBUG - Contraseña correcta
2025-03-12 21:54:29,532 - DEBUG - Intento de inicio de sesión: admin@shelly.local
2025-03-12 21:54:29,539 - DEBUG - Usuario encontrado en la base de datos
2025-03-12 21:54:29,879 - DEBUG - Contraseña correcta
2025-03-12 22:00:28,256 - INFO - 🔧 Backend Flask iniciado.
2025-03-12 22:04:50,073 - DEBUG - Intento de inicio de sesión: admin@shelly.local
2025-03-12 22:04:50,087 - DEBUG - Usuario encontrado en la base de datos
2025-03-12 22:04:50,426 - DEBUG - Contraseña correcta
2025-03-13 04:23:12,993 - DEBUG - Intento de inicio de sesión: admin@shelly.local
2025-03-13 04:23:13,000 - DEBUG - Usuario encontrado en la base de datos
2025-03-13 04:23:13,339 - DEBUG - Contraseña correcta
2025-03-13 04:35:53,762 - DEBUG - Intento de inicio de sesión: admin@shelly.local
2025-03-13 04:35:53,765 - DEBUG - Usuario encontrado en la base de datos
2025-03-13 04:35:54,103 - DEBUG - Contraseña correcta
2025-03-13 04:40:03,072 - DEBUG - Intento de inicio de sesión: admin@shelly.local
2025-03-13 04:40:03,081 - DEBUG - Usuario encontrado en la base de datos
2025-03-13 04:40:03,428 - DEBUG - Contraseña correcta
2025-03-13 04:41:41,150 - DEBUG - Intento de inicio de sesión: admin@shelly.local
2025-03-13 04:41:41,153 - DEBUG - Usuario encontrado en la base de datos
2025-03-13 04:41:41,497 - DEBUG - Contraseña correcta
2025-03-13 04:52:28,726 - DEBUG - Intento de inicio de sesión: admin@shelly.local
2025-03-13 04:52:28,729 - DEBUG - Usuario encontrado en la base de datos
2025-03-13 04:52:29,074 - DEBUG - Contraseña correcta
2025-03-13 04:57:15,305 - INFO - 🔧 Backend Flask iniciado.
2025-03-13 04:57:47,990 - INFO - 🔧 Backend Flask iniciado.
2025-03-13 04:58:11,133 - DEBUG - Intento de inicio de sesión: admin@shelly.local
2025-03-13 04:58:11,143 - DEBUG - Usuario encontrado en la base de datos
2025-03-13 04:58:11,482 - DEBUG - Contraseña correcta
2025-03-13 05:29:29,354 - DEBUG - Intento de inicio de sesión: admin@shelly.local
2025-03-13 05:29:29,360 - DEBUG - Usuario encontrado en la base de datos
2025-03-13 05:29:29,700 - DEBUG - Contraseña correcta
2025-03-13 05:55:50,532 - DEBUG - Intento de inicio de sesión: admin@shelly.local
2025-03-13 05:55:50,538 - DEBUG - Usuario encontrado en la base de datos
2025-03-13 05:55:50,878 - DEBUG - Contraseña correcta
2025-03-13 19:21:49,221 - INFO - 🔧 Backend Flask iniciado.
2025-03-13 19:23:19,661 - INFO - 🔧 Backend Flask iniciado.
2025-03-13 19:51:00,042 - DEBUG - Intento de inicio de sesión: admin@shelly.local
2025-03-13 19:51:00,055 - DEBUG - Usuario encontrado en la base de datos
2025-03-13 19:51:00,394 - DEBUG - Contraseña correcta
2025-03-13 20:59:06,867 - INFO - 🔧 Backend Flask iniciado.
2025-03-13 21:00:53,667 - DEBUG - Intento de inicio de sesión: admin@shelly.local
2025-03-13 21:00:53,676 - DEBUG - Usuario encontrado en la base de datos
2025-03-13 21:00:54,017 - DEBUG - Contraseña correcta
2025-03-13 21:07:09,521 - DEBUG - Intento de inicio de sesión: admin@shelly.local
2025-03-13 21:07:09,524 - DEBUG - Usuario encontrado en la base de datos
2025-03-13 21:07:09,866 - DEBUG - Contraseña correcta
2025-03-13 21:09:34,889 - DEBUG - Intento de inicio de sesión: admin@shelly.local
2025-03-13 21:09:34,895 - DEBUG - Usuario encontrado en la base de datos
2025-03-13 21:09:35,240 - DEBUG - Contraseña correcta
2025-03-13 21:12:30,533 - DEBUG - Intento de inicio de sesión: admin@shelly.local
2025-03-13 21:12:30,537 - DEBUG - Usuario encontrado en la base de datos
2025-03-13 21:12:30,877 - DEBUG - Contraseña correcta
2025-03-13 21:17:01,262 - DEBUG - Intento de inicio de sesión: admin@shelly.local
2025-03-13 21:17:01,264 - DEBUG - Usuario encontrado en la base de datos
2025-03-13 21:17:01,608 - DEBUG - Contraseña correcta
2025-03-13 21:33:39,358 - DEBUG - Intento de inicio de sesión: admin@shelly.local
2025-03-13 21:33:39,361 - DEBUG - Usuario encontrado en la base de datos
2025-03-13 21:33:39,703 - DEBUG - Contraseña correcta
2025-03-13 21:37:42,580 - DEBUG - Intento de inicio de sesión: admin@shelly.local
2025-03-13 21:37:42,587 - DEBUG - Usuario encontrado en la base de datos
2025-03-13 21:37:42,928 - DEBUG - Contraseña correcta
2025-03-13 21:47:42,248 - DEBUG - Intento de inicio de sesión: admin@shelly.local
2025-03-13 21:47:42,253 - DEBUG - Usuario encontrado en la base de datos
2025-03-13 21:47:42,596 - DEBUG - Contraseña correcta
2025-03-13 21:58:20,893 - DEBUG - Intento de inicio de sesión: admin@shelly.local
2025-03-13 21:58:20,896 - DEBUG - Usuario encontrado en la base de datos
2025-03-13 21:58:21,243 - DEBUG - Contraseña correcta
2025-03-13 22:24:31,605 - INFO - 🔧 Backend Flask iniciado.
2025-03-14 01:16:48,355 - DEBUG - Intento de inicio de sesión: admin@shelly.local
2025-03-14 01:16:48,368 - DEBUG - Usuario encontrado en la base de datos
2025-03-14 01:16:48,708 - DEBUG - Contraseña correcta
2025-03-14 01:40:25,895 - INFO - 🔧 Backend Flask iniciado.
2025-03-14 01:41:22,146 - DEBUG - Intento de inicio de sesión: admin@shelly.local
2025-03-14 01:41:22,156 - DEBUG - Usuario encontrado en la base de datos
2025-03-14 01:41:22,496 - DEBUG - Contraseña correcta
2025-03-14 01:51:18,395 - INFO - 🔧 Backend Flask iniciado.
2025-03-14 01:55:31,305 - DEBUG - Intento de inicio de sesión: admin@shelly.local
2025-03-14 01:55:31,315 - DEBUG - Usuario encontrado en la base de datos
2025-03-14 01:55:31,660 - DEBUG - Contraseña correcta
2025-03-14 03:02:23,576 - DEBUG - Intento de inicio de sesión: admin@shelly.local
2025-03-14 03:02:23,580 - DEBUG - Usuario encontrado en la base de datos
2025-03-14 03:02:23,920 - DEBUG - Contraseña correcta
2025-03-14 03:17:22,120 - DEBUG - Intento de inicio de sesión: admin@shelly.local
2025-03-14 03:17:22,122 - DEBUG - Usuario encontrado en la base de datos
2025-03-14 03:17:22,462 - DEBUG - Contraseña correcta
2025-03-14 03:23:57,142 - DEBUG - Intento de inicio de sesión: admin@shelly.local
2025-03-14 03:23:57,145 - DEBUG - Usuario encontrado en la base de datos
2025-03-14 03:23:57,485 - DEBUG - Contraseña correcta
2025-03-14 03:37:11,932 - DEBUG - Intento de inicio de sesión: admin@shelly.local
2025-03-14 03:37:11,942 - DEBUG - Usuario encontrado en la base de datos
2025-03-14 03:37:12,283 - DEBUG - Contraseña correcta
2025-03-14 13:07:04,148 - INFO - 🔧 Backend Flask iniciado.
2025-03-14 13:08:27,086 - INFO - 🔧 Backend Flask iniciado.
2025-03-14 13:09:06,748 - DEBUG - Intento de inicio de sesión: admin@shelly.local
2025-03-14 13:09:06,758 - DEBUG - Usuario encontrado en la base de datos
2025-03-14 13:09:07,104 - DEBUG - Contraseña correcta
2025-03-14 13:09:29,491 - DEBUG - Intento de inicio de sesión: admin@shelly.local
2025-03-14 13:09:29,493 - DEBUG - Usuario encontrado en la base de datos
2025-03-14 13:09:29,842 - DEBUG - Contraseña correcta
2025-03-14 13:10:06,320 - DEBUG - Intento de inicio de sesión: admin@shelly.local
2025-03-14 13:10:06,322 - DEBUG - Usuario encontrado en la base de datos
2025-03-14 13:10:06,661 - DEBUG - Contraseña correcta
2025-03-14 13:11:38,974 - DEBUG - Intento de inicio de sesión: admin@shelly.local
2025-03-14 13:11:38,976 - DEBUG - Usuario encontrado en la base de datos
2025-03-14 13:11:39,327 - DEBUG - Contraseña correcta
2025-03-14 13:12:34,585 - DEBUG - Intento de inicio de sesión: admin@shelly.local
2025-03-14 13:12:34,588 - DEBUG - Usuario encontrado en la base de datos
2025-03-14 13:12:34,927 - DEBUG - Contraseña correcta
2025-03-14 13:13:24,194 - DEBUG - Intento de inicio de sesión: admin@shelly.local
2025-03-14 13:13:24,196 - DEBUG - Usuario encontrado en la base de datos
2025-03-14 13:13:24,538 - DEBUG - Contraseña correcta
2025-03-14 13:17:32,918 - INFO - 🔧 Backend Flask iniciado.
2025-03-14 13:17:43,665 - INFO - 🔧 Backend Flask iniciado.
2025-03-14 14:05:04,994 - INFO - 🔧 Backend Flask iniciado.
2025-03-14 14:05:31,514 - DEBUG - Intento de inicio de sesión: admin@shelly.local
2025-03-14 14:05:31,525 - DEBUG - Usuario encontrado en la base de datos
2025-03-14 14:05:31,864 - DEBUG - Contraseña correcta
2025-03-14 14:09:38,013 - INFO - 🔧 Backend Flask iniciado.
2025-03-14 14:09:54,319 - DEBUG - Intento de inicio de sesión: admin@shelly.local
2025-03-14 14:09:54,329 - DEBUG - Usuario encontrado en la base de datos
2025-03-14 14:09:54,671 - DEBUG - Contraseña correcta
2025-03-14 14:11:22,719 - INFO - 🔧 Backend Flask iniciado.
2025-03-14 14:11:33,338 - DEBUG - Intento de inicio de sesión: admin@shelly.local
2025-03-14 14:11:33,348 - DEBUG - Usuario encontrado en la base de datos
2025-03-14 14:11:33,690 - DEBUG - Contraseña correcta
2025-03-14 14:12:01,404 - DEBUG - Intento de inicio de sesión: admin@shelly.local
2025-03-14 14:12:01,407 - DEBUG - Usuario encontrado en la base de datos
2025-03-14 14:12:01,747 - DEBUG - Contraseña correcta
2025-03-14 14:28:29,292 - DEBUG - Intento de inicio de sesión: admin@shelly.local
2025-03-14 14:28:29,295 - DEBUG - Usuario encontrado en la base de datos
2025-03-14 14:28:29,637 - DEBUG - Contraseña correcta
2025-03-14 14:33:36,334 - DEBUG - Intento de inicio de sesión: admin@shelly.local
2025-03-14 14:33:36,339 - DEBUG - Usuario encontrado en la base de datos
2025-03-14 14:33:36,681 - DEBUG - Contraseña correcta
2025-03-14 14:51:05,610 - DEBUG - Intento de inicio de sesión: admin@shelly.local
2025-03-14 14:51:05,616 - DEBUG - Usuario encontrado en la base de datos
2025-03-14 14:51:05,962 - DEBUG - Contraseña correcta
2025-03-14 14:54:26,333 - DEBUG - Intento de inicio de sesión: admin@shelly.local
2025-03-14 14:54:26,336 - DEBUG - Usuario encontrado en la base de datos
2025-03-14 14:54:26,677 - DEBUG - Contraseña correcta
2025-03-14 16:15:21,941 - DEBUG - Intento de inicio de sesión: admin@shelly.local
2025-03-14 16:15:21,945 - DEBUG - Usuario encontrado en la base de datos
2025-03-14 16:15:22,285 - DEBUG - Contraseña correcta
2025-03-14 17:05:04,092 - INFO - 🔧 Backend Flask iniciado.
2025-03-14 17:34:21,954 - INFO - 🔧 Backend Flask iniciado.
2025-03-14 18:02:28,675 - INFO - 🔧 Backend Flask iniciado.
2025-03-14 18:31:33,064 - DEBUG - Intento de inicio de sesión: admin@shelly.local
2025-03-14 18:31:33,076 - DEBUG - Usuario encontrado en la base de datos
2025-03-14 18:31:33,418 - DEBUG - Contraseña correcta
2025-03-14 19:23:54,319 - DEBUG - Intento de inicio de sesión: admin@shelly.local
2025-03-14 19:23:54,325 - DEBUG - Usuario encontrado en la base de datos
2025-03-14 19:23:54,665 - DEBUG - Contraseña correcta
2025-03-14 19:27:04,387 - DEBUG - Intento de inicio de sesión: admin@shelly.local
2025-03-14 19:27:04,390 - DEBUG - Usuario encontrado en la base de datos
2025-03-14 19:27:04,732 - DEBUG - Contraseña correcta
2025-03-14 20:46:15,055 - INFO - 🔧 Backend Flask iniciado.
2025-03-14 20:46:51,311 - DEBUG - Intento de inicio de sesión: admin@shelly.local
2025-03-14 20:46:51,321 - DEBUG - Usuario encontrado en la base de datos
2025-03-14 20:46:51,667 - DEBUG - Contraseña correcta
2025-03-14 20:47:52,170 - ERROR - Exception on /api/tableros [GET]
Traceback (most recent call last):
  File "/opt/shelly_monitoring/venv/lib/python3.12/site-packages/sqlalchemy/engine/base.py", line 1964, in _exec_single_context
    self.dialect.do_execute(
  File "/opt/shelly_monitoring/venv/lib/python3.12/site-packages/sqlalchemy/engine/default.py", line 942, in do_execute
    cursor.execute(statement, parameters)
psycopg2.errors.UndefinedColumn: column tableros.orden does not exist
LINE 1: ... tableros_id, tableros.nombre AS tableros_nombre, tableros.o...
                                                             ^


The above exception was the direct cause of the following exception:

Traceback (most recent call last):
  File "/opt/shelly_monitoring/venv/lib/python3.12/site-packages/flask/app.py", line 1511, in wsgi_app
    response = self.full_dispatch_request()
               ^^^^^^^^^^^^^^^^^^^^^^^^^^^^
  File "/opt/shelly_monitoring/venv/lib/python3.12/site-packages/flask/app.py", line 919, in full_dispatch_request
    rv = self.handle_user_exception(e)
         ^^^^^^^^^^^^^^^^^^^^^^^^^^^^^
  File "/opt/shelly_monitoring/venv/lib/python3.12/site-packages/flask_cors/extension.py", line 176, in wrapped_function
    return cors_after_request(app.make_response(f(*args, **kwargs)))
                                                ^^^^^^^^^^^^^^^^^^
  File "/opt/shelly_monitoring/venv/lib/python3.12/site-packages/flask/app.py", line 917, in full_dispatch_request
    rv = self.dispatch_request()
         ^^^^^^^^^^^^^^^^^^^^^^^
  File "/opt/shelly_monitoring/venv/lib/python3.12/site-packages/flask/app.py", line 902, in dispatch_request
    return self.ensure_sync(self.view_functions[rule.endpoint])(**view_args)  # type: ignore[no-any-return]
           ^^^^^^^^^^^^^^^^^^^^^^^^^^^^^^^^^^^^^^^^^^^^^^^^^^^^^^^^^^^^^^^^^
  File "/opt/shelly_monitoring/app.py", line 73, in decorated_function
    return f(*args, **kwargs)
           ^^^^^^^^^^^^^^^^^^
  File "/opt/shelly_monitoring/app.py", line 234, in get_tableros
    tableros = Tableros.query.all()
               ^^^^^^^^^^^^^^^^^^^^
  File "/opt/shelly_monitoring/venv/lib/python3.12/site-packages/sqlalchemy/orm/query.py", line 2704, in all
    return self._iter().all()  # type: ignore
           ^^^^^^^^^^^^
  File "/opt/shelly_monitoring/venv/lib/python3.12/site-packages/sqlalchemy/orm/query.py", line 2858, in _iter
    result: Union[ScalarResult[_T], Result[_T]] = self.session.execute(
                                                  ^^^^^^^^^^^^^^^^^^^^^
  File "/opt/shelly_monitoring/venv/lib/python3.12/site-packages/sqlalchemy/orm/session.py", line 2365, in execute
    return self._execute_internal(
           ^^^^^^^^^^^^^^^^^^^^^^^
  File "/opt/shelly_monitoring/venv/lib/python3.12/site-packages/sqlalchemy/orm/session.py", line 2251, in _execute_internal
    result: Result[Any] = compile_state_cls.orm_execute_statement(
                          ^^^^^^^^^^^^^^^^^^^^^^^^^^^^^^^^^^^^^^^^
  File "/opt/shelly_monitoring/venv/lib/python3.12/site-packages/sqlalchemy/orm/context.py", line 306, in orm_execute_statement
    result = conn.execute(
             ^^^^^^^^^^^^^
  File "/opt/shelly_monitoring/venv/lib/python3.12/site-packages/sqlalchemy/engine/base.py", line 1416, in execute
    return meth(
           ^^^^^
  File "/opt/shelly_monitoring/venv/lib/python3.12/site-packages/sqlalchemy/sql/elements.py", line 523, in _execute_on_connection
    return connection._execute_clauseelement(
           ^^^^^^^^^^^^^^^^^^^^^^^^^^^^^^^^^^
  File "/opt/shelly_monitoring/venv/lib/python3.12/site-packages/sqlalchemy/engine/base.py", line 1638, in _execute_clauseelement
    ret = self._execute_context(
          ^^^^^^^^^^^^^^^^^^^^^^
  File "/opt/shelly_monitoring/venv/lib/python3.12/site-packages/sqlalchemy/engine/base.py", line 1843, in _execute_context
    return self._exec_single_context(
           ^^^^^^^^^^^^^^^^^^^^^^^^^^
  File "/opt/shelly_monitoring/venv/lib/python3.12/site-packages/sqlalchemy/engine/base.py", line 1983, in _exec_single_context
    self._handle_dbapi_exception(
  File "/opt/shelly_monitoring/venv/lib/python3.12/site-packages/sqlalchemy/engine/base.py", line 2352, in _handle_dbapi_exception
    raise sqlalchemy_exception.with_traceback(exc_info[2]) from e
  File "/opt/shelly_monitoring/venv/lib/python3.12/site-packages/sqlalchemy/engine/base.py", line 1964, in _exec_single_context
    self.dialect.do_execute(
  File "/opt/shelly_monitoring/venv/lib/python3.12/site-packages/sqlalchemy/engine/default.py", line 942, in do_execute
    cursor.execute(statement, parameters)
sqlalchemy.exc.ProgrammingError: (psycopg2.errors.UndefinedColumn) column tableros.orden does not exist
LINE 1: ... tableros_id, tableros.nombre AS tableros_nombre, tableros.o...
                                                             ^

[SQL: SELECT tableros.id AS tableros_id, tableros.nombre AS tableros_nombre, tableros.orden AS tableros_orden 
FROM tableros]
(Background on this error at: https://sqlalche.me/e/20/f405)
2025-03-14 20:50:22,265 - DEBUG - Intento de inicio de sesión: admin@shelly.local
2025-03-14 20:50:22,267 - DEBUG - Usuario encontrado en la base de datos
2025-03-14 20:50:22,608 - DEBUG - Contraseña correcta
2025-03-14 20:50:39,971 - ERROR - Exception on /api/tableros [GET]
Traceback (most recent call last):
  File "/opt/shelly_monitoring/venv/lib/python3.12/site-packages/sqlalchemy/engine/base.py", line 1964, in _exec_single_context
    self.dialect.do_execute(
  File "/opt/shelly_monitoring/venv/lib/python3.12/site-packages/sqlalchemy/engine/default.py", line 942, in do_execute
    cursor.execute(statement, parameters)
psycopg2.errors.UndefinedColumn: column tableros.orden does not exist
LINE 1: ... tableros_id, tableros.nombre AS tableros_nombre, tableros.o...
                                                             ^


The above exception was the direct cause of the following exception:

Traceback (most recent call last):
  File "/opt/shelly_monitoring/venv/lib/python3.12/site-packages/flask/app.py", line 1511, in wsgi_app
    response = self.full_dispatch_request()
               ^^^^^^^^^^^^^^^^^^^^^^^^^^^^
  File "/opt/shelly_monitoring/venv/lib/python3.12/site-packages/flask/app.py", line 919, in full_dispatch_request
    rv = self.handle_user_exception(e)
         ^^^^^^^^^^^^^^^^^^^^^^^^^^^^^
  File "/opt/shelly_monitoring/venv/lib/python3.12/site-packages/flask_cors/extension.py", line 176, in wrapped_function
    return cors_after_request(app.make_response(f(*args, **kwargs)))
                                                ^^^^^^^^^^^^^^^^^^
  File "/opt/shelly_monitoring/venv/lib/python3.12/site-packages/flask/app.py", line 917, in full_dispatch_request
    rv = self.dispatch_request()
         ^^^^^^^^^^^^^^^^^^^^^^^
  File "/opt/shelly_monitoring/venv/lib/python3.12/site-packages/flask/app.py", line 902, in dispatch_request
    return self.ensure_sync(self.view_functions[rule.endpoint])(**view_args)  # type: ignore[no-any-return]
           ^^^^^^^^^^^^^^^^^^^^^^^^^^^^^^^^^^^^^^^^^^^^^^^^^^^^^^^^^^^^^^^^^
  File "/opt/shelly_monitoring/app.py", line 73, in decorated_function
    return f(*args, **kwargs)
           ^^^^^^^^^^^^^^^^^^
  File "/opt/shelly_monitoring/app.py", line 234, in get_tableros
    tableros = Tableros.query.all()
               ^^^^^^^^^^^^^^^^^^^^
  File "/opt/shelly_monitoring/venv/lib/python3.12/site-packages/sqlalchemy/orm/query.py", line 2704, in all
    return self._iter().all()  # type: ignore
           ^^^^^^^^^^^^
  File "/opt/shelly_monitoring/venv/lib/python3.12/site-packages/sqlalchemy/orm/query.py", line 2858, in _iter
    result: Union[ScalarResult[_T], Result[_T]] = self.session.execute(
                                                  ^^^^^^^^^^^^^^^^^^^^^
  File "/opt/shelly_monitoring/venv/lib/python3.12/site-packages/sqlalchemy/orm/session.py", line 2365, in execute
    return self._execute_internal(
           ^^^^^^^^^^^^^^^^^^^^^^^
  File "/opt/shelly_monitoring/venv/lib/python3.12/site-packages/sqlalchemy/orm/session.py", line 2251, in _execute_internal
    result: Result[Any] = compile_state_cls.orm_execute_statement(
                          ^^^^^^^^^^^^^^^^^^^^^^^^^^^^^^^^^^^^^^^^
  File "/opt/shelly_monitoring/venv/lib/python3.12/site-packages/sqlalchemy/orm/context.py", line 306, in orm_execute_statement
    result = conn.execute(
             ^^^^^^^^^^^^^
  File "/opt/shelly_monitoring/venv/lib/python3.12/site-packages/sqlalchemy/engine/base.py", line 1416, in execute
    return meth(
           ^^^^^
  File "/opt/shelly_monitoring/venv/lib/python3.12/site-packages/sqlalchemy/sql/elements.py", line 523, in _execute_on_connection
    return connection._execute_clauseelement(
           ^^^^^^^^^^^^^^^^^^^^^^^^^^^^^^^^^^
  File "/opt/shelly_monitoring/venv/lib/python3.12/site-packages/sqlalchemy/engine/base.py", line 1638, in _execute_clauseelement
    ret = self._execute_context(
          ^^^^^^^^^^^^^^^^^^^^^^
  File "/opt/shelly_monitoring/venv/lib/python3.12/site-packages/sqlalchemy/engine/base.py", line 1843, in _execute_context
    return self._exec_single_context(
           ^^^^^^^^^^^^^^^^^^^^^^^^^^
  File "/opt/shelly_monitoring/venv/lib/python3.12/site-packages/sqlalchemy/engine/base.py", line 1983, in _exec_single_context
    self._handle_dbapi_exception(
  File "/opt/shelly_monitoring/venv/lib/python3.12/site-packages/sqlalchemy/engine/base.py", line 2352, in _handle_dbapi_exception
    raise sqlalchemy_exception.with_traceback(exc_info[2]) from e
  File "/opt/shelly_monitoring/venv/lib/python3.12/site-packages/sqlalchemy/engine/base.py", line 1964, in _exec_single_context
    self.dialect.do_execute(
  File "/opt/shelly_monitoring/venv/lib/python3.12/site-packages/sqlalchemy/engine/default.py", line 942, in do_execute
    cursor.execute(statement, parameters)
sqlalchemy.exc.ProgrammingError: (psycopg2.errors.UndefinedColumn) column tableros.orden does not exist
LINE 1: ... tableros_id, tableros.nombre AS tableros_nombre, tableros.o...
                                                             ^

[SQL: SELECT tableros.id AS tableros_id, tableros.nombre AS tableros_nombre, tableros.orden AS tableros_orden 
FROM tableros]
(Background on this error at: https://sqlalche.me/e/20/f405)
2025-03-14 20:52:36,290 - DEBUG - Intento de inicio de sesión: admin@shelly.local
2025-03-14 20:52:36,293 - DEBUG - Usuario encontrado en la base de datos
2025-03-14 20:52:36,632 - DEBUG - Contraseña correcta
2025-03-14 20:53:08,014 - ERROR - Exception on /api/tableros [GET]
Traceback (most recent call last):
  File "/opt/shelly_monitoring/venv/lib/python3.12/site-packages/sqlalchemy/engine/base.py", line 1964, in _exec_single_context
    self.dialect.do_execute(
  File "/opt/shelly_monitoring/venv/lib/python3.12/site-packages/sqlalchemy/engine/default.py", line 942, in do_execute
    cursor.execute(statement, parameters)
psycopg2.errors.UndefinedColumn: column tableros.orden does not exist
LINE 1: ... tableros_id, tableros.nombre AS tableros_nombre, tableros.o...
                                                             ^


The above exception was the direct cause of the following exception:

Traceback (most recent call last):
  File "/opt/shelly_monitoring/venv/lib/python3.12/site-packages/flask/app.py", line 1511, in wsgi_app
    response = self.full_dispatch_request()
               ^^^^^^^^^^^^^^^^^^^^^^^^^^^^
  File "/opt/shelly_monitoring/venv/lib/python3.12/site-packages/flask/app.py", line 919, in full_dispatch_request
    rv = self.handle_user_exception(e)
         ^^^^^^^^^^^^^^^^^^^^^^^^^^^^^
  File "/opt/shelly_monitoring/venv/lib/python3.12/site-packages/flask_cors/extension.py", line 176, in wrapped_function
    return cors_after_request(app.make_response(f(*args, **kwargs)))
                                                ^^^^^^^^^^^^^^^^^^
  File "/opt/shelly_monitoring/venv/lib/python3.12/site-packages/flask/app.py", line 917, in full_dispatch_request
    rv = self.dispatch_request()
         ^^^^^^^^^^^^^^^^^^^^^^^
  File "/opt/shelly_monitoring/venv/lib/python3.12/site-packages/flask/app.py", line 902, in dispatch_request
    return self.ensure_sync(self.view_functions[rule.endpoint])(**view_args)  # type: ignore[no-any-return]
           ^^^^^^^^^^^^^^^^^^^^^^^^^^^^^^^^^^^^^^^^^^^^^^^^^^^^^^^^^^^^^^^^^
  File "/opt/shelly_monitoring/app.py", line 73, in decorated_function
    return f(*args, **kwargs)
           ^^^^^^^^^^^^^^^^^^
  File "/opt/shelly_monitoring/app.py", line 234, in get_tableros
    tableros = Tableros.query.all()
               ^^^^^^^^^^^^^^^^^^^^
  File "/opt/shelly_monitoring/venv/lib/python3.12/site-packages/sqlalchemy/orm/query.py", line 2704, in all
    return self._iter().all()  # type: ignore
           ^^^^^^^^^^^^
  File "/opt/shelly_monitoring/venv/lib/python3.12/site-packages/sqlalchemy/orm/query.py", line 2858, in _iter
    result: Union[ScalarResult[_T], Result[_T]] = self.session.execute(
                                                  ^^^^^^^^^^^^^^^^^^^^^
  File "/opt/shelly_monitoring/venv/lib/python3.12/site-packages/sqlalchemy/orm/session.py", line 2365, in execute
    return self._execute_internal(
           ^^^^^^^^^^^^^^^^^^^^^^^
  File "/opt/shelly_monitoring/venv/lib/python3.12/site-packages/sqlalchemy/orm/session.py", line 2251, in _execute_internal
    result: Result[Any] = compile_state_cls.orm_execute_statement(
                          ^^^^^^^^^^^^^^^^^^^^^^^^^^^^^^^^^^^^^^^^
  File "/opt/shelly_monitoring/venv/lib/python3.12/site-packages/sqlalchemy/orm/context.py", line 306, in orm_execute_statement
    result = conn.execute(
             ^^^^^^^^^^^^^
  File "/opt/shelly_monitoring/venv/lib/python3.12/site-packages/sqlalchemy/engine/base.py", line 1416, in execute
    return meth(
           ^^^^^
  File "/opt/shelly_monitoring/venv/lib/python3.12/site-packages/sqlalchemy/sql/elements.py", line 523, in _execute_on_connection
    return connection._execute_clauseelement(
           ^^^^^^^^^^^^^^^^^^^^^^^^^^^^^^^^^^
  File "/opt/shelly_monitoring/venv/lib/python3.12/site-packages/sqlalchemy/engine/base.py", line 1638, in _execute_clauseelement
    ret = self._execute_context(
          ^^^^^^^^^^^^^^^^^^^^^^
  File "/opt/shelly_monitoring/venv/lib/python3.12/site-packages/sqlalchemy/engine/base.py", line 1843, in _execute_context
    return self._exec_single_context(
           ^^^^^^^^^^^^^^^^^^^^^^^^^^
  File "/opt/shelly_monitoring/venv/lib/python3.12/site-packages/sqlalchemy/engine/base.py", line 1983, in _exec_single_context
    self._handle_dbapi_exception(
  File "/opt/shelly_monitoring/venv/lib/python3.12/site-packages/sqlalchemy/engine/base.py", line 2352, in _handle_dbapi_exception
    raise sqlalchemy_exception.with_traceback(exc_info[2]) from e
  File "/opt/shelly_monitoring/venv/lib/python3.12/site-packages/sqlalchemy/engine/base.py", line 1964, in _exec_single_context
    self.dialect.do_execute(
  File "/opt/shelly_monitoring/venv/lib/python3.12/site-packages/sqlalchemy/engine/default.py", line 942, in do_execute
    cursor.execute(statement, parameters)
sqlalchemy.exc.ProgrammingError: (psycopg2.errors.UndefinedColumn) column tableros.orden does not exist
LINE 1: ... tableros_id, tableros.nombre AS tableros_nombre, tableros.o...
                                                             ^

[SQL: SELECT tableros.id AS tableros_id, tableros.nombre AS tableros_nombre, tableros.orden AS tableros_orden 
FROM tableros]
(Background on this error at: https://sqlalche.me/e/20/f405)
2025-03-14 20:54:08,497 - DEBUG - Intento de inicio de sesión: admin@shelly.local
2025-03-14 20:54:08,501 - DEBUG - Usuario encontrado en la base de datos
2025-03-14 20:54:08,840 - DEBUG - Contraseña correcta
2025-03-14 20:54:14,158 - ERROR - Exception on /api/tableros [GET]
Traceback (most recent call last):
  File "/opt/shelly_monitoring/venv/lib/python3.12/site-packages/sqlalchemy/engine/base.py", line 1964, in _exec_single_context
    self.dialect.do_execute(
  File "/opt/shelly_monitoring/venv/lib/python3.12/site-packages/sqlalchemy/engine/default.py", line 942, in do_execute
    cursor.execute(statement, parameters)
psycopg2.errors.UndefinedColumn: column tableros.orden does not exist
LINE 1: ... tableros_id, tableros.nombre AS tableros_nombre, tableros.o...
                                                             ^


The above exception was the direct cause of the following exception:

Traceback (most recent call last):
  File "/opt/shelly_monitoring/venv/lib/python3.12/site-packages/flask/app.py", line 1511, in wsgi_app
    response = self.full_dispatch_request()
               ^^^^^^^^^^^^^^^^^^^^^^^^^^^^
  File "/opt/shelly_monitoring/venv/lib/python3.12/site-packages/flask/app.py", line 919, in full_dispatch_request
    rv = self.handle_user_exception(e)
         ^^^^^^^^^^^^^^^^^^^^^^^^^^^^^
  File "/opt/shelly_monitoring/venv/lib/python3.12/site-packages/flask_cors/extension.py", line 176, in wrapped_function
    return cors_after_request(app.make_response(f(*args, **kwargs)))
                                                ^^^^^^^^^^^^^^^^^^
  File "/opt/shelly_monitoring/venv/lib/python3.12/site-packages/flask/app.py", line 917, in full_dispatch_request
    rv = self.dispatch_request()
         ^^^^^^^^^^^^^^^^^^^^^^^
  File "/opt/shelly_monitoring/venv/lib/python3.12/site-packages/flask/app.py", line 902, in dispatch_request
    return self.ensure_sync(self.view_functions[rule.endpoint])(**view_args)  # type: ignore[no-any-return]
           ^^^^^^^^^^^^^^^^^^^^^^^^^^^^^^^^^^^^^^^^^^^^^^^^^^^^^^^^^^^^^^^^^
  File "/opt/shelly_monitoring/app.py", line 73, in decorated_function
    return f(*args, **kwargs)
           ^^^^^^^^^^^^^^^^^^
  File "/opt/shelly_monitoring/app.py", line 234, in get_tableros
    tableros = Tableros.query.all()
               ^^^^^^^^^^^^^^^^^^^^
  File "/opt/shelly_monitoring/venv/lib/python3.12/site-packages/sqlalchemy/orm/query.py", line 2704, in all
    return self._iter().all()  # type: ignore
           ^^^^^^^^^^^^
  File "/opt/shelly_monitoring/venv/lib/python3.12/site-packages/sqlalchemy/orm/query.py", line 2858, in _iter
    result: Union[ScalarResult[_T], Result[_T]] = self.session.execute(
                                                  ^^^^^^^^^^^^^^^^^^^^^
  File "/opt/shelly_monitoring/venv/lib/python3.12/site-packages/sqlalchemy/orm/session.py", line 2365, in execute
    return self._execute_internal(
           ^^^^^^^^^^^^^^^^^^^^^^^
  File "/opt/shelly_monitoring/venv/lib/python3.12/site-packages/sqlalchemy/orm/session.py", line 2251, in _execute_internal
    result: Result[Any] = compile_state_cls.orm_execute_statement(
                          ^^^^^^^^^^^^^^^^^^^^^^^^^^^^^^^^^^^^^^^^
  File "/opt/shelly_monitoring/venv/lib/python3.12/site-packages/sqlalchemy/orm/context.py", line 306, in orm_execute_statement
    result = conn.execute(
             ^^^^^^^^^^^^^
  File "/opt/shelly_monitoring/venv/lib/python3.12/site-packages/sqlalchemy/engine/base.py", line 1416, in execute
    return meth(
           ^^^^^
  File "/opt/shelly_monitoring/venv/lib/python3.12/site-packages/sqlalchemy/sql/elements.py", line 523, in _execute_on_connection
    return connection._execute_clauseelement(
           ^^^^^^^^^^^^^^^^^^^^^^^^^^^^^^^^^^
  File "/opt/shelly_monitoring/venv/lib/python3.12/site-packages/sqlalchemy/engine/base.py", line 1638, in _execute_clauseelement
    ret = self._execute_context(
          ^^^^^^^^^^^^^^^^^^^^^^
  File "/opt/shelly_monitoring/venv/lib/python3.12/site-packages/sqlalchemy/engine/base.py", line 1843, in _execute_context
    return self._exec_single_context(
           ^^^^^^^^^^^^^^^^^^^^^^^^^^
  File "/opt/shelly_monitoring/venv/lib/python3.12/site-packages/sqlalchemy/engine/base.py", line 1983, in _exec_single_context
    self._handle_dbapi_exception(
  File "/opt/shelly_monitoring/venv/lib/python3.12/site-packages/sqlalchemy/engine/base.py", line 2352, in _handle_dbapi_exception
    raise sqlalchemy_exception.with_traceback(exc_info[2]) from e
  File "/opt/shelly_monitoring/venv/lib/python3.12/site-packages/sqlalchemy/engine/base.py", line 1964, in _exec_single_context
    self.dialect.do_execute(
  File "/opt/shelly_monitoring/venv/lib/python3.12/site-packages/sqlalchemy/engine/default.py", line 942, in do_execute
    cursor.execute(statement, parameters)
sqlalchemy.exc.ProgrammingError: (psycopg2.errors.UndefinedColumn) column tableros.orden does not exist
LINE 1: ... tableros_id, tableros.nombre AS tableros_nombre, tableros.o...
                                                             ^

[SQL: SELECT tableros.id AS tableros_id, tableros.nombre AS tableros_nombre, tableros.orden AS tableros_orden 
FROM tableros]
(Background on this error at: https://sqlalche.me/e/20/f405)
2025-03-14 21:07:33,369 - DEBUG - Intento de inicio de sesión: admin@shelly.local
2025-03-14 21:07:33,372 - DEBUG - Usuario encontrado en la base de datos
2025-03-14 21:07:33,711 - DEBUG - Contraseña correcta
2025-03-14 21:27:58,211 - DEBUG - Intento de inicio de sesión: admin@shelly.local
2025-03-14 21:27:58,213 - DEBUG - Usuario encontrado en la base de datos
2025-03-14 21:27:58,553 - DEBUG - Contraseña correcta
2025-03-14 21:28:44,305 - DEBUG - Intento de inicio de sesión: admin@shelly.local
2025-03-14 21:28:44,307 - DEBUG - Usuario encontrado en la base de datos
2025-03-14 21:28:44,647 - DEBUG - Contraseña correcta
2025-03-14 22:26:02,264 - DEBUG - Intento de inicio de sesión: admin@shelly.local
2025-03-14 22:26:02,268 - DEBUG - Usuario encontrado en la base de datos
2025-03-14 22:26:02,608 - DEBUG - Contraseña correcta
2025-03-14 22:29:02,566 - INFO - 🔧 Backend Flask iniciado.
2025-03-14 22:29:20,662 - DEBUG - Intento de inicio de sesión: admin@shelly.local
2025-03-14 22:29:20,672 - DEBUG - Usuario encontrado en la base de datos
2025-03-14 22:29:21,014 - DEBUG - Contraseña correcta
2025-03-14 22:35:33,657 - DEBUG - Intento de inicio de sesión: admin@shelly.local
2025-03-14 22:35:33,660 - DEBUG - Usuario encontrado en la base de datos
2025-03-14 22:35:34,008 - DEBUG - Contraseña correcta
2025-03-14 22:40:43,646 - DEBUG - Intento de inicio de sesión: admin@shelly.local
2025-03-14 22:40:43,649 - DEBUG - Usuario encontrado en la base de datos
2025-03-14 22:40:43,989 - DEBUG - Contraseña correcta
2025-03-14 22:46:37,402 - DEBUG - Intento de inicio de sesión: admin@shelly.local
2025-03-14 22:46:37,499 - DEBUG - Usuario encontrado en la base de datos
2025-03-14 22:46:37,842 - DEBUG - Contraseña correcta
2025-03-14 23:01:12,741 - DEBUG - Intento de inicio de sesión: admin@shelly.local
2025-03-14 23:01:12,747 - DEBUG - Usuario encontrado en la base de datos
2025-03-14 23:01:13,095 - DEBUG - Contraseña correcta
2025-03-14 23:01:37,989 - DEBUG - Intento de inicio de sesión: admin@shelly.local
2025-03-14 23:01:37,992 - DEBUG - Usuario encontrado en la base de datos
2025-03-14 23:01:38,332 - DEBUG - Contraseña correcta
2025-03-14 23:04:02,355 - INFO - 🔧 Backend Flask iniciado.
2025-03-14 23:04:20,318 - DEBUG - Intento de inicio de sesión: admin@shelly.local
2025-03-14 23:04:20,328 - DEBUG - Usuario encontrado en la base de datos
2025-03-14 23:04:20,667 - DEBUG - Contraseña correcta
2025-03-14 23:04:22,287 - DEBUG - Intento de inicio de sesión: admin@shelly.local
2025-03-14 23:04:22,289 - DEBUG - Usuario encontrado en la base de datos
2025-03-14 23:04:22,628 - DEBUG - Contraseña correcta
2025-03-14 23:09:21,204 - DEBUG - Intento de inicio de sesión: admin@shelly.local
2025-03-14 23:09:21,207 - DEBUG - Usuario encontrado en la base de datos
2025-03-14 23:09:21,553 - DEBUG - Contraseña correcta
2025-03-14 23:11:30,478 - DEBUG - Intento de inicio de sesión: admin@shelly.local
2025-03-14 23:11:30,481 - DEBUG - Usuario encontrado en la base de datos
2025-03-14 23:11:30,821 - DEBUG - Contraseña correcta
2025-03-15 14:23:57,585 - DEBUG - Intento de inicio de sesión: admin@shelly.local
2025-03-15 14:23:57,592 - DEBUG - Usuario encontrado en la base de datos
2025-03-15 14:23:57,932 - DEBUG - Contraseña correcta
2025-03-15 20:34:37,689 - INFO - 🔧 Backend Flask iniciado.
2025-03-15 20:49:14,476 - DEBUG - Intento de inicio de sesión: admin@shelly.local
2025-03-15 20:49:14,492 - DEBUG - Usuario encontrado en la base de datos
2025-03-15 20:49:14,830 - DEBUG - Contraseña correcta
2025-03-15 20:57:06,263 - INFO - 🔧 Backend Flask iniciado.
2025-03-15 20:57:47,165 - INFO - 🔧 Backend Flask iniciado.
2025-03-15 20:59:39,130 - DEBUG - Intento de inicio de sesión: admin@shelly.local
2025-03-15 20:59:39,141 - DEBUG - Usuario encontrado en la base de datos
2025-03-15 20:59:39,480 - DEBUG - Contraseña correcta
2025-03-15 21:05:15,769 - INFO - 🔧 Backend Flask iniciado.
2025-03-15 21:07:05,977 - DEBUG - Intento de inicio de sesión: admin@shelly.local
2025-03-15 21:07:05,989 - DEBUG - Usuario encontrado en la base de datos
2025-03-15 21:07:06,331 - DEBUG - Contraseña correcta
2025-03-16 14:02:16,445 - INFO - 🔧 Backend Flask iniciado.
2025-03-16 14:08:33,831 - DEBUG - Intento de inicio de sesión: admin@shelly.local
2025-03-16 14:08:33,843 - DEBUG - Usuario encontrado en la base de datos
2025-03-16 14:08:34,183 - DEBUG - Contraseña correcta
2025-03-16 14:13:38,097 - DEBUG - Intento de inicio de sesión: admin@shelly.local
2025-03-16 14:13:38,100 - DEBUG - Usuario encontrado en la base de datos
2025-03-16 14:13:38,438 - DEBUG - Contraseña correcta
2025-03-16 14:27:15,813 - DEBUG - Intento de inicio de sesión: admin@shelly.local
2025-03-16 14:27:15,817 - DEBUG - Usuario encontrado en la base de datos
2025-03-16 14:27:16,156 - DEBUG - Contraseña correcta
2025-03-16 14:46:25,678 - INFO - 🔧 Backend Flask iniciado.
2025-03-16 14:46:27,358 - INFO - 🔧 Backend Flask iniciado.
2025-03-16 14:46:29,168 - INFO - 🔧 Backend Flask iniciado.
2025-03-16 14:46:30,893 - INFO - 🔧 Backend Flask iniciado.
2025-03-16 14:46:32,603 - INFO - 🔧 Backend Flask iniciado.
2025-03-16 14:49:28,802 - INFO - 🔧 Backend Flask iniciado.
2025-03-16 14:49:30,640 - INFO - 🔧 Backend Flask iniciado.
2025-03-16 14:49:32,392 - INFO - 🔧 Backend Flask iniciado.
2025-03-16 14:49:34,151 - INFO - 🔧 Backend Flask iniciado.
2025-03-16 14:49:36,131 - INFO - 🔧 Backend Flask iniciado.
2025-03-16 15:09:29,761 - INFO - 🔧 Backend Flask iniciado.
2025-03-16 15:16:31,749 - INFO - 🔧 Backend Flask iniciado.
2025-03-16 15:29:05,540 - INFO - 🔧 Backend Flask iniciado.
2025-03-16 15:29:07,382 - INFO - 🔧 Backend Flask iniciado.
2025-03-16 15:29:09,129 - INFO - 🔧 Backend Flask iniciado.
2025-03-16 15:29:10,884 - INFO - 🔧 Backend Flask iniciado.
2025-03-16 15:29:12,638 - INFO - 🔧 Backend Flask iniciado.
2025-03-16 15:31:56,651 - INFO - 🔧 Backend Flask iniciado.
2025-03-16 15:32:18,495 - DEBUG - Intento de inicio de sesión: admin@shelly.local
2025-03-16 15:32:18,505 - DEBUG - Usuario encontrado en la base de datos
2025-03-16 15:32:18,844 - DEBUG - Contraseña correcta
2025-03-17 00:45:01,310 - INFO - 🔧 Backend Flask iniciado.
2025-03-17 00:45:45,644 - INFO - 🔧 Backend Flask iniciado.
2025-03-17 00:46:00,528 - DEBUG - Intento de inicio de sesión: admin@shelly.local
2025-03-17 00:46:00,537 - DEBUG - Usuario encontrado en la base de datos
2025-03-17 00:46:00,877 - DEBUG - Contraseña correcta
2025-03-17 00:51:16,742 - DEBUG - Intento de inicio de sesión: admin@shelly.local
2025-03-17 00:51:16,745 - DEBUG - Usuario encontrado en la base de datos
2025-03-17 00:51:17,085 - DEBUG - Contraseña correcta
2025-03-17 00:55:49,981 - INFO - 🔧 Backend Flask iniciado.
2025-03-17 00:56:06,842 - DEBUG - Intento de inicio de sesión: admin@shelly.local
2025-03-17 00:56:06,853 - DEBUG - Usuario encontrado en la base de datos
2025-03-17 00:56:07,192 - DEBUG - Contraseña correcta
2025-03-17 00:57:28,752 - INFO - 🔧 Backend Flask iniciado.
2025-03-17 00:58:25,457 - INFO - 🔧 Backend Flask iniciado.
2025-03-17 00:58:37,399 - INFO - 🔧 Backend Flask iniciado.
2025-03-17 00:58:51,474 - DEBUG - Intento de inicio de sesión: admin@shelly.local
2025-03-17 00:58:51,483 - DEBUG - Usuario encontrado en la base de datos
2025-03-17 00:58:51,825 - DEBUG - Contraseña correcta
2025-03-17 02:23:23,306 - DEBUG - Intento de inicio de sesión: admin@shelly.local
2025-03-17 02:23:23,310 - DEBUG - Usuario encontrado en la base de datos
2025-03-17 02:23:23,648 - DEBUG - Contraseña correcta
2025-03-17 02:34:39,596 - DEBUG - Intento de inicio de sesión: admin@shelly.local
2025-03-17 02:34:39,599 - DEBUG - Usuario encontrado en la base de datos
2025-03-17 02:34:39,938 - DEBUG - Contraseña correcta
2025-03-17 02:35:23,634 - DEBUG - Intento de inicio de sesión: admin@shelly.local
2025-03-17 02:35:23,636 - DEBUG - Usuario encontrado en la base de datos
2025-03-17 02:35:23,975 - DEBUG - Contraseña correcta
2025-03-17 02:47:18,943 - DEBUG - Intento de inicio de sesión: admin@shelly.local
2025-03-17 02:47:18,946 - DEBUG - Usuario encontrado en la base de datos
2025-03-17 02:47:19,286 - DEBUG - Contraseña correcta
2025-03-17 03:06:05,391 - INFO - 🔧 Backend Flask iniciado.
2025-03-17 03:07:21,054 - DEBUG - Intento de inicio de sesión: admin@shelly.local
2025-03-17 03:07:21,063 - DEBUG - Usuario encontrado en la base de datos
2025-03-17 03:07:21,402 - DEBUG - Contraseña correcta
2025-03-17 03:07:23,387 - DEBUG - Authorization header: Bearer eyJhbGciOiJIUzI1NiIsInR5cCI6IkpXVCJ9.eyJ1c2VyX2lkIjoxfQ.Ql2z3Q06DCptkiE0oobOYogpNccHD86O59NyCHWf7sk
2025-03-17 03:07:23,388 - DEBUG - Token válido para el usuario: 1
2025-03-17 03:15:40,367 - INFO - 🔧 Backend Flask iniciado.
2025-03-17 03:17:42,046 - DEBUG - Intento de inicio de sesión: admin@shelly.local
2025-03-17 03:17:42,054 - DEBUG - Usuario encontrado en la base de datos
2025-03-17 03:17:42,396 - DEBUG - Contraseña correcta
2025-03-17 03:17:44,526 - DEBUG - Authorization header: Bearer eyJhbGciOiJIUzI1NiIsInR5cCI6IkpXVCJ9.eyJ1c2VyX2lkIjoxfQ.Ql2z3Q06DCptkiE0oobOYogpNccHD86O59NyCHWf7sk
2025-03-17 03:17:44,526 - DEBUG - Token válido para el usuario: 1
2025-03-17 03:17:46,640 - DEBUG - Verificando permisos para el usuario: None
2025-03-17 03:17:46,640 - DEBUG - Usuario no autenticado
2025-03-17 03:17:50,058 - DEBUG - Verificando permisos para el usuario: None
2025-03-17 03:17:50,059 - DEBUG - Usuario no autenticado
2025-03-17 03:17:51,139 - DEBUG - Verificando permisos para el usuario: None
2025-03-17 03:17:51,139 - DEBUG - Usuario no autenticado
2025-03-17 03:22:35,008 - INFO - 🔧 Backend Flask iniciado.
2025-03-17 03:27:56,034 - DEBUG - Intento de inicio de sesión: admin@shelly.local
2025-03-17 03:27:56,045 - DEBUG - Usuario encontrado en la base de datos
2025-03-17 03:27:56,384 - DEBUG - Contraseña correcta
2025-03-17 03:28:41,990 - DEBUG - Intento de inicio de sesión: admin@shelly.local
2025-03-17 03:28:41,993 - DEBUG - Usuario encontrado en la base de datos
2025-03-17 03:28:42,333 - DEBUG - Contraseña correcta
2025-03-17 03:28:44,788 - DEBUG - Authorization header: Bearer eyJhbGciOiJIUzI1NiIsInR5cCI6IkpXVCJ9.eyJ1c2VyX2lkIjoxfQ.Ql2z3Q06DCptkiE0oobOYogpNccHD86O59NyCHWf7sk
2025-03-17 03:28:44,788 - DEBUG - Token válido para el usuario: 1
2025-03-17 03:28:47,457 - DEBUG - Verificando permisos para el usuario: None
2025-03-17 03:28:47,457 - DEBUG - Usuario no autenticado
2025-03-17 03:28:50,443 - DEBUG - Verificando permisos para el usuario: None
2025-03-17 03:28:50,444 - DEBUG - Usuario no autenticado
2025-03-17 03:28:51,409 - DEBUG - Verificando permisos para el usuario: None
2025-03-17 03:28:51,409 - DEBUG - Usuario no autenticado
2025-03-17 03:29:52,096 - DEBUG - Intento de inicio de sesión: admin@shelly.local
2025-03-17 03:29:52,099 - DEBUG - Usuario encontrado en la base de datos
2025-03-17 03:29:52,439 - DEBUG - Contraseña correcta
2025-03-17 03:29:54,481 - DEBUG - Authorization header: Bearer eyJhbGciOiJIUzI1NiIsInR5cCI6IkpXVCJ9.eyJ1c2VyX2lkIjoxfQ.Ql2z3Q06DCptkiE0oobOYogpNccHD86O59NyCHWf7sk
2025-03-17 03:29:54,482 - DEBUG - Token válido para el usuario: 1
2025-03-17 03:29:56,520 - DEBUG - Verificando permisos para el usuario: None
2025-03-17 03:29:56,520 - DEBUG - Usuario no autenticado
2025-03-17 03:29:59,619 - DEBUG - Verificando permisos para el usuario: None
2025-03-17 03:29:59,619 - DEBUG - Usuario no autenticado
2025-03-17 03:30:00,770 - DEBUG - Verificando permisos para el usuario: None
2025-03-17 03:30:00,771 - DEBUG - Usuario no autenticado
2025-03-17 03:31:28,859 - INFO - 🔧 Backend Flask iniciado.
2025-03-17 03:33:29,333 - DEBUG - Intento de inicio de sesión: admin@shelly.local
2025-03-17 03:33:29,342 - DEBUG - Usuario encontrado en la base de datos
2025-03-17 03:33:29,681 - DEBUG - Contraseña correcta
2025-03-17 03:33:31,537 - DEBUG - Authorization header: Bearer eyJhbGciOiJIUzI1NiIsInR5cCI6IkpXVCJ9.eyJ1c2VyX2lkIjoxfQ.Ql2z3Q06DCptkiE0oobOYogpNccHD86O59NyCHWf7sk
2025-03-17 03:33:31,537 - DEBUG - Token válido para el usuario: 1
2025-03-17 03:33:33,622 - DEBUG - Verificando permisos para el usuario: None
2025-03-17 03:33:33,622 - DEBUG - Usuario no autenticado
2025-03-17 03:33:36,870 - DEBUG - Verificando permisos para el usuario: None
2025-03-17 03:33:36,870 - DEBUG - Usuario no autenticado
2025-03-17 03:33:38,079 - DEBUG - Verificando permisos para el usuario: None
2025-03-17 03:33:38,079 - DEBUG - Usuario no autenticado
2025-03-17 03:34:42,182 - DEBUG - Intento de inicio de sesión: admin@shelly.local
2025-03-17 03:34:42,184 - DEBUG - Usuario encontrado en la base de datos
2025-03-17 03:34:42,524 - DEBUG - Contraseña correcta
2025-03-17 03:38:31,767 - INFO - 🔧 Backend Flask iniciado.
2025-03-17 03:39:39,206 - DEBUG - Intento de inicio de sesión: admin@shelly.local
2025-03-17 03:39:39,206 - ERROR - Exception on /api/login [POST]
Traceback (most recent call last):
  File "/opt/shelly_monitoring/venv/lib/python3.12/site-packages/flask/app.py", line 1511, in wsgi_app
    response = self.full_dispatch_request()
               ^^^^^^^^^^^^^^^^^^^^^^^^^^^^
  File "/opt/shelly_monitoring/venv/lib/python3.12/site-packages/flask/app.py", line 919, in full_dispatch_request
    rv = self.handle_user_exception(e)
         ^^^^^^^^^^^^^^^^^^^^^^^^^^^^^
  File "/opt/shelly_monitoring/venv/lib/python3.12/site-packages/flask_cors/extension.py", line 176, in wrapped_function
    return cors_after_request(app.make_response(f(*args, **kwargs)))
                                                ^^^^^^^^^^^^^^^^^^
  File "/opt/shelly_monitoring/venv/lib/python3.12/site-packages/flask/app.py", line 917, in full_dispatch_request
    rv = self.dispatch_request()
         ^^^^^^^^^^^^^^^^^^^^^^^
  File "/opt/shelly_monitoring/venv/lib/python3.12/site-packages/flask/app.py", line 902, in dispatch_request
    return self.ensure_sync(self.view_functions[rule.endpoint])(**view_args)  # type: ignore[no-any-return]
           ^^^^^^^^^^^^^^^^^^^^^^^^^^^^^^^^^^^^^^^^^^^^^^^^^^^^^^^^^^^^^^^^^
  File "/opt/shelly_monitoring/app.py", line 102, in login
    user = User.query.filter_by(email=email).first()
           ^^^^
NameError: name 'User' is not defined
2025-03-17 03:40:54,522 - DEBUG - Intento de inicio de sesión: admin@shelly.local
2025-03-17 03:40:54,522 - ERROR - Exception on /api/login [POST]
Traceback (most recent call last):
  File "/opt/shelly_monitoring/venv/lib/python3.12/site-packages/flask/app.py", line 1511, in wsgi_app
    response = self.full_dispatch_request()
               ^^^^^^^^^^^^^^^^^^^^^^^^^^^^
  File "/opt/shelly_monitoring/venv/lib/python3.12/site-packages/flask/app.py", line 919, in full_dispatch_request
    rv = self.handle_user_exception(e)
         ^^^^^^^^^^^^^^^^^^^^^^^^^^^^^
  File "/opt/shelly_monitoring/venv/lib/python3.12/site-packages/flask_cors/extension.py", line 176, in wrapped_function
    return cors_after_request(app.make_response(f(*args, **kwargs)))
                                                ^^^^^^^^^^^^^^^^^^
  File "/opt/shelly_monitoring/venv/lib/python3.12/site-packages/flask/app.py", line 917, in full_dispatch_request
    rv = self.dispatch_request()
         ^^^^^^^^^^^^^^^^^^^^^^^
  File "/opt/shelly_monitoring/venv/lib/python3.12/site-packages/flask/app.py", line 902, in dispatch_request
    return self.ensure_sync(self.view_functions[rule.endpoint])(**view_args)  # type: ignore[no-any-return]
           ^^^^^^^^^^^^^^^^^^^^^^^^^^^^^^^^^^^^^^^^^^^^^^^^^^^^^^^^^^^^^^^^^
  File "/opt/shelly_monitoring/app.py", line 102, in login
    user = User.query.filter_by(email=email).first()
           ^^^^
NameError: name 'User' is not defined
2025-03-17 03:42:47,670 - INFO - 🔧 Backend Flask iniciado.
2025-03-17 03:43:48,461 - DEBUG - Intento de inicio de sesión: admin@shelly.local
2025-03-17 03:43:48,462 - ERROR - Exception on /api/login [POST]
Traceback (most recent call last):
  File "/opt/shelly_monitoring/venv/lib/python3.12/site-packages/flask/app.py", line 1511, in wsgi_app
    response = self.full_dispatch_request()
               ^^^^^^^^^^^^^^^^^^^^^^^^^^^^
  File "/opt/shelly_monitoring/venv/lib/python3.12/site-packages/flask/app.py", line 919, in full_dispatch_request
    rv = self.handle_user_exception(e)
         ^^^^^^^^^^^^^^^^^^^^^^^^^^^^^
  File "/opt/shelly_monitoring/venv/lib/python3.12/site-packages/flask_cors/extension.py", line 176, in wrapped_function
    return cors_after_request(app.make_response(f(*args, **kwargs)))
                                                ^^^^^^^^^^^^^^^^^^
  File "/opt/shelly_monitoring/venv/lib/python3.12/site-packages/flask/app.py", line 917, in full_dispatch_request
    rv = self.dispatch_request()
         ^^^^^^^^^^^^^^^^^^^^^^^
  File "/opt/shelly_monitoring/venv/lib/python3.12/site-packages/flask/app.py", line 902, in dispatch_request
    return self.ensure_sync(self.view_functions[rule.endpoint])(**view_args)  # type: ignore[no-any-return]
           ^^^^^^^^^^^^^^^^^^^^^^^^^^^^^^^^^^^^^^^^^^^^^^^^^^^^^^^^^^^^^^^^^
  File "/opt/shelly_monitoring/app.py", line 102, in login
    user = User.query.filter_by(email=email).first()
           ^^^^
NameError: name 'User' is not defined
2025-03-17 03:48:01,246 - INFO - 🔧 Backend Flask iniciado.
2025-03-17 03:49:16,367 - DEBUG - Intento de inicio de sesión: admin@shelly.local
2025-03-17 03:49:16,368 - ERROR - Exception on /api/login [POST]
Traceback (most recent call last):
  File "/opt/shelly_monitoring/venv/lib/python3.12/site-packages/flask/app.py", line 1511, in wsgi_app
    response = self.full_dispatch_request()
               ^^^^^^^^^^^^^^^^^^^^^^^^^^^^
  File "/opt/shelly_monitoring/venv/lib/python3.12/site-packages/flask/app.py", line 919, in full_dispatch_request
    rv = self.handle_user_exception(e)
         ^^^^^^^^^^^^^^^^^^^^^^^^^^^^^
  File "/opt/shelly_monitoring/venv/lib/python3.12/site-packages/flask_cors/extension.py", line 176, in wrapped_function
    return cors_after_request(app.make_response(f(*args, **kwargs)))
                                                ^^^^^^^^^^^^^^^^^^
  File "/opt/shelly_monitoring/venv/lib/python3.12/site-packages/flask/app.py", line 917, in full_dispatch_request
    rv = self.dispatch_request()
         ^^^^^^^^^^^^^^^^^^^^^^^
  File "/opt/shelly_monitoring/venv/lib/python3.12/site-packages/flask/app.py", line 902, in dispatch_request
    return self.ensure_sync(self.view_functions[rule.endpoint])(**view_args)  # type: ignore[no-any-return]
           ^^^^^^^^^^^^^^^^^^^^^^^^^^^^^^^^^^^^^^^^^^^^^^^^^^^^^^^^^^^^^^^^^
  File "/opt/shelly_monitoring/app.py", line 102, in login
    user = User.query.filter_by(email=email).first()
           ^^^^
NameError: name 'User' is not defined
2025-03-17 04:22:35,726 - INFO - 🔧 Backend Flask iniciado.
2025-03-17 04:24:19,678 - DEBUG - Intento de inicio de sesión: admin@shelly.local
2025-03-17 04:24:19,687 - DEBUG - Usuario encontrado en la base de datos
2025-03-17 04:24:20,026 - DEBUG - Contraseña correcta
2025-03-17 04:24:21,929 - DEBUG - Authorization header: Bearer eyJhbGciOiJIUzI1NiIsInR5cCI6IkpXVCJ9.eyJ1c2VyX2lkIjoxfQ.Ql2z3Q06DCptkiE0oobOYogpNccHD86O59NyCHWf7sk
2025-03-17 04:24:21,930 - DEBUG - Token válido para el usuario: 1
2025-03-17 04:24:24,178 - DEBUG - Verificando permisos para el usuario: None
2025-03-17 04:24:24,178 - DEBUG - Usuario no autenticado
2025-03-17 04:24:27,460 - DEBUG - Verificando permisos para el usuario: None
2025-03-17 04:24:27,460 - DEBUG - Usuario no autenticado
2025-03-17 04:24:28,617 - DEBUG - Verificando permisos para el usuario: None
2025-03-17 04:24:28,617 - DEBUG - Usuario no autenticado
2025-03-17 04:29:18,895 - INFO - 🔧 Backend Flask iniciado.
2025-03-17 04:30:37,547 - DEBUG - Intento de inicio de sesión: admin@shelly.local
2025-03-17 04:30:37,556 - DEBUG - Usuario encontrado en la base de datos
2025-03-17 04:30:37,896 - DEBUG - Contraseña correcta
2025-03-17 04:30:40,262 - DEBUG - Authorization header: Bearer eyJhbGciOiJIUzI1NiIsInR5cCI6IkpXVCJ9.eyJ1c2VyX2lkIjoxfQ.Ql2z3Q06DCptkiE0oobOYogpNccHD86O59NyCHWf7sk
2025-03-17 04:30:40,262 - DEBUG - Token válido para el usuario: 1
2025-03-17 04:30:42,140 - DEBUG - Verificando permisos para el usuario: None
2025-03-17 04:30:42,140 - DEBUG - Usuario no autenticado
2025-03-17 04:30:45,179 - DEBUG - Verificando permisos para el usuario: None
2025-03-17 04:30:45,179 - DEBUG - Usuario no autenticado
2025-03-17 04:30:46,167 - DEBUG - Verificando permisos para el usuario: None
2025-03-17 04:30:46,167 - DEBUG - Usuario no autenticado
2025-03-17 04:45:14,402 - INFO - 🔧 Backend Flask iniciado.
2025-03-17 04:46:26,342 - DEBUG - Intento de inicio de sesión: admin@shelly.local
2025-03-17 04:46:26,358 - DEBUG - Usuario encontrado en la base de datos
2025-03-17 04:46:26,702 - DEBUG - Contraseña correcta
2025-03-17 04:46:28,810 - DEBUG - Authorization header: Bearer eyJhbGciOiJIUzI1NiIsInR5cCI6IkpXVCJ9.eyJ1c2VyX2lkIjoxfQ.Ql2z3Q06DCptkiE0oobOYogpNccHD86O59NyCHWf7sk
2025-03-17 04:46:28,812 - DEBUG - Token válido para el usuario: 1
2025-03-17 04:46:30,644 - DEBUG - Verificando permisos para el usuario: None
2025-03-17 04:46:30,644 - DEBUG - Usuario no autenticado
2025-03-17 04:46:33,842 - DEBUG - Verificando permisos para el usuario: None
2025-03-17 04:46:33,842 - DEBUG - Usuario no autenticado
2025-03-17 04:46:34,821 - DEBUG - Verificando permisos para el usuario: None
2025-03-17 04:46:34,821 - DEBUG - Usuario no autenticado
2025-03-17 05:00:05,194 - INFO - 🔧 Backend Flask iniciado.
2025-03-17 05:01:08,123 - DEBUG - Intento de inicio de sesión: admin@shelly.local
2025-03-17 05:01:08,132 - DEBUG - Usuario encontrado en la base de datos
2025-03-17 05:01:08,475 - DEBUG - Contraseña correcta
2025-03-17 05:01:10,430 - DEBUG - Authorization header: Bearer eyJhbGciOiJIUzI1NiIsInR5cCI6IkpXVCJ9.eyJ1c2VyX2lkIjoxfQ.Ql2z3Q06DCptkiE0oobOYogpNccHD86O59NyCHWf7sk
2025-03-17 05:01:10,430 - DEBUG - Token válido para el usuario: 1
2025-03-17 05:01:12,320 - DEBUG - Verificando permisos para el usuario: None
2025-03-17 05:01:12,320 - DEBUG - Usuario no autenticado: session.get('user_id') devolvió None
2025-03-17 05:01:15,616 - DEBUG - Verificando permisos para el usuario: None
2025-03-17 05:01:15,616 - DEBUG - Usuario no autenticado: session.get('user_id') devolvió None
2025-03-17 05:01:16,828 - DEBUG - Verificando permisos para el usuario: None
2025-03-17 05:01:16,828 - DEBUG - Usuario no autenticado: session.get('user_id') devolvió None
2025-03-17 05:06:12,207 - INFO - 🔧 Backend Flask iniciado.
2025-03-17 05:07:08,299 - DEBUG - Intento de inicio de sesión: admin@shelly.local
2025-03-17 05:07:08,308 - DEBUG - Usuario encontrado en la base de datos
2025-03-17 05:07:08,649 - DEBUG - Contraseña correcta
2025-03-17 05:07:11,057 - DEBUG - Authorization header: Bearer eyJhbGciOiJIUzI1NiIsInR5cCI6IkpXVCJ9.eyJ1c2VyX2lkIjoxfQ.Ql2z3Q06DCptkiE0oobOYogpNccHD86O59NyCHWf7sk
2025-03-17 05:07:11,058 - DEBUG - Token válido para el usuario: 1
2025-03-17 05:07:12,906 - DEBUG - Verificando permisos para el usuario: None
2025-03-17 05:07:12,906 - DEBUG - Usuario no autenticado: session.get('user_id') devolvió None
2025-03-17 05:07:16,065 - DEBUG - Verificando permisos para el usuario: None
2025-03-17 05:07:16,065 - DEBUG - Usuario no autenticado: session.get('user_id') devolvió None
2025-03-17 05:07:17,145 - DEBUG - Verificando permisos para el usuario: None
2025-03-17 05:07:17,145 - DEBUG - Usuario no autenticado: session.get('user_id') devolvió None
2025-03-17 12:09:41,390 - INFO - 🔧 Backend Flask iniciado.
2025-03-17 12:10:53,523 - INFO - 🔧 Backend Flask iniciado.
2025-03-17 12:13:28,795 - INFO - 🔧 Backend Flask iniciado.
2025-03-17 12:13:57,285 - DEBUG - Intento de inicio de sesión: admin@shelly.local
2025-03-17 12:13:57,295 - DEBUG - Usuario encontrado en la base de datos
2025-03-17 12:13:57,634 - DEBUG - Contraseña correcta
2025-03-17 12:13:57,982 - DEBUG - Authorization header: Bearer eyJhbGciOiJIUzI1NiIsInR5cCI6IkpXVCJ9.eyJ1c2VyX2lkIjoxfQ.Ql2z3Q06DCptkiE0oobOYogpNccHD86O59NyCHWf7sk
2025-03-17 12:13:57,982 - DEBUG - Decoded user_id: 1
2025-03-17 12:13:57,982 - DEBUG - Token válido para el usuario: 1
2025-03-17 12:13:58,351 - DEBUG - Verificando permisos para el usuario: None
2025-03-17 12:13:58,352 - DEBUG - Usuario no autenticado: session.get('user_id') devolvió None
2025-03-17 12:13:58,733 - DEBUG - Verificando permisos para el usuario: None
2025-03-17 12:13:58,733 - DEBUG - Usuario no autenticado: session.get('user_id') devolvió None
2025-03-17 12:13:58,748 - DEBUG - Verificando permisos para el usuario: None
2025-03-17 12:13:58,748 - DEBUG - Usuario no autenticado: session.get('user_id') devolvió None
2025-03-17 12:15:42,807 - DEBUG - Verificando permisos para el usuario: None
2025-03-17 12:15:42,807 - DEBUG - Usuario no autenticado: session.get('user_id') devolvió None
2025-03-17 12:15:43,344 - DEBUG - Verificando permisos para el usuario: None
2025-03-17 12:15:43,344 - DEBUG - Usuario no autenticado: session.get('user_id') devolvió None
2025-03-17 12:15:43,540 - DEBUG - Verificando permisos para el usuario: None
2025-03-17 12:15:43,540 - DEBUG - Usuario no autenticado: session.get('user_id') devolvió None
2025-03-17 12:15:58,452 - DEBUG - Verificando permisos para el usuario: None
2025-03-17 12:15:58,452 - DEBUG - Usuario no autenticado: session.get('user_id') devolvió None
2025-03-17 12:15:59,047 - DEBUG - Verificando permisos para el usuario: None
2025-03-17 12:15:59,047 - DEBUG - Usuario no autenticado: session.get('user_id') devolvió None
2025-03-17 12:15:59,233 - DEBUG - Verificando permisos para el usuario: None
2025-03-17 12:15:59,233 - DEBUG - Usuario no autenticado: session.get('user_id') devolvió None
2025-03-17 12:16:05,692 - DEBUG - Verificando permisos para el usuario: None
2025-03-17 12:16:05,692 - DEBUG - Usuario no autenticado: session.get('user_id') devolvió None
2025-03-17 12:16:06,076 - DEBUG - Verificando permisos para el usuario: None
2025-03-17 12:16:06,076 - DEBUG - Usuario no autenticado: session.get('user_id') devolvió None
2025-03-17 12:16:06,077 - DEBUG - Verificando permisos para el usuario: None
2025-03-17 12:16:06,077 - DEBUG - Usuario no autenticado: session.get('user_id') devolvió None
2025-03-17 12:17:38,103 - INFO - 🔧 Backend Flask iniciado.
2025-03-17 12:18:04,621 - DEBUG - Intento de inicio de sesión: admin@shelly.local
2025-03-17 12:18:04,632 - DEBUG - Usuario encontrado en la base de datos
2025-03-17 12:18:04,973 - DEBUG - Contraseña correcta
2025-03-17 12:18:06,870 - DEBUG - Authorization header: Bearer eyJhbGciOiJIUzI1NiIsInR5cCI6IkpXVCJ9.eyJ1c2VyX2lkIjoxfQ.Ql2z3Q06DCptkiE0oobOYogpNccHD86O59NyCHWf7sk
2025-03-17 12:18:06,870 - DEBUG - Decoded user_id: 1
2025-03-17 12:18:06,870 - DEBUG - Token válido para el usuario: 1
2025-03-17 12:18:07,382 - DEBUG - Verificando permisos para el usuario: None
2025-03-17 12:18:07,382 - DEBUG - Usuario no autenticado: session.get('user_id') devolvió None
2025-03-17 12:18:08,017 - DEBUG - Verificando permisos para el usuario: None
2025-03-17 12:18:08,017 - DEBUG - Usuario no autenticado: session.get('user_id') devolvió None
2025-03-17 12:18:08,184 - DEBUG - Verificando permisos para el usuario: None
2025-03-17 12:18:08,184 - DEBUG - Usuario no autenticado: session.get('user_id') devolvió None
2025-03-17 12:18:57,953 - DEBUG - Intento de inicio de sesión: admin@shelly.local
2025-03-17 12:18:57,956 - DEBUG - Usuario encontrado en la base de datos
2025-03-17 12:18:58,295 - DEBUG - Contraseña correcta
2025-03-17 12:20:07,945 - DEBUG - Verificando permisos para el usuario: None
2025-03-17 12:20:07,946 - DEBUG - Usuario no autenticado: session.get('user_id') devolvió None
2025-03-17 12:22:07,054 - INFO - 🔧 Backend Flask iniciado.
2025-03-17 12:22:29,729 - DEBUG - Intento de inicio de sesión: admin@shelly.local
2025-03-17 12:22:29,739 - DEBUG - Usuario encontrado en la base de datos
2025-03-17 12:22:30,079 - DEBUG - Contraseña correcta
2025-03-17 12:22:30,535 - DEBUG - Authorization header: Bearer eyJhbGciOiJIUzI1NiIsInR5cCI6IkpXVCJ9.eyJ1c2VyX2lkIjoxfQ.Ql2z3Q06DCptkiE0oobOYogpNccHD86O59NyCHWf7sk
2025-03-17 12:22:30,535 - DEBUG - Decoded user_id: 1
2025-03-17 12:22:30,535 - DEBUG - Token válido para el usuario: 1
2025-03-17 12:22:31,166 - DEBUG - Verificando permisos para el usuario: None
2025-03-17 12:22:31,167 - DEBUG - Usuario no autenticado: session.get('user_id') devolvió None
2025-03-17 12:22:31,844 - DEBUG - Verificando permisos para el usuario: None
2025-03-17 12:22:31,844 - DEBUG - Usuario no autenticado: session.get('user_id') devolvió None
2025-03-17 12:22:31,846 - DEBUG - Verificando permisos para el usuario: None
2025-03-17 12:22:31,847 - DEBUG - Usuario no autenticado: session.get('user_id') devolvió None
2025-03-17 12:22:46,261 - DEBUG - Verificando permisos para el usuario: None
2025-03-17 12:22:46,261 - DEBUG - Usuario no autenticado: session.get('user_id') devolvió None
2025-03-17 12:22:46,423 - DEBUG - Verificando permisos para el usuario: None
2025-03-17 12:22:46,423 - DEBUG - Usuario no autenticado: session.get('user_id') devolvió None
2025-03-17 12:43:53,971 - INFO - 🔧 Backend Flask iniciado.
2025-03-17 12:44:18,426 - DEBUG - Intento de inicio de sesión: admin@shelly.local
2025-03-17 12:44:18,436 - DEBUG - Usuario encontrado en la base de datos
2025-03-17 12:44:18,776 - DEBUG - Contraseña correcta
2025-03-17 12:44:18,776 - DEBUG - Token generado: eyJhbGciOiJIUzI1NiIsInR5cCI6IkpXVCJ9.eyJ1c2VyX2lkIjoxfQ.Ql2z3Q06DCptkiE0oobOYogpNccHD86O59NyCHWf7sk
2025-03-17 12:44:19,111 - DEBUG - Ejecutando middleware require_login
2025-03-17 12:44:19,111 - DEBUG - Authorization header: Bearer eyJhbGciOiJIUzI1NiIsInR5cCI6IkpXVCJ9.eyJ1c2VyX2lkIjoxfQ.Ql2z3Q06DCptkiE0oobOYogpNccHD86O59NyCHWf7sk
2025-03-17 12:44:19,111 - DEBUG - Token recibido: eyJhbGciOiJIUzI1NiIsInR5cCI6IkpXVCJ9.eyJ1c2VyX2lkIjoxfQ.Ql2z3Q06DCptkiE0oobOYogpNccHD86O59NyCHWf7sk
2025-03-17 12:44:19,112 - DEBUG - Token decodificado correctamente, user_id: 1
2025-03-17 12:44:19,112 - DEBUG - Sesión configurada para el usuario: 1
2025-03-17 12:44:19,464 - DEBUG - Verificando permisos para el usuario: None
2025-03-17 12:44:19,464 - DEBUG - Usuario no autenticado: session.get('user_id') devolvió None
2025-03-17 12:44:19,843 - DEBUG - Verificando permisos para el usuario: None
2025-03-17 12:44:19,844 - DEBUG - Usuario no autenticado: session.get('user_id') devolvió None
2025-03-17 12:44:19,845 - DEBUG - Verificando permisos para el usuario: None
2025-03-17 12:44:19,845 - DEBUG - Usuario no autenticado: session.get('user_id') devolvió None
2025-03-17 12:51:47,071 - INFO - 🔧 Backend Flask iniciado.
2025-03-17 12:52:19,912 - DEBUG - Intento de inicio de sesión: admin@shelly.local
2025-03-17 12:52:19,923 - DEBUG - Usuario encontrado en la base de datos
2025-03-17 12:52:20,263 - DEBUG - Contraseña correcta
2025-03-17 12:52:20,263 - DEBUG - Token generado: eyJhbGciOiJIUzI1NiIsInR5cCI6IkpXVCJ9.eyJ1c2VyX2lkIjoxfQ.Ql2z3Q06DCptkiE0oobOYogpNccHD86O59NyCHWf7sk
2025-03-17 12:52:20,604 - DEBUG - Ejecutando middleware require_login
2025-03-17 12:52:20,604 - DEBUG - Authorization header: Bearer eyJhbGciOiJIUzI1NiIsInR5cCI6IkpXVCJ9.eyJ1c2VyX2lkIjoxfQ.Ql2z3Q06DCptkiE0oobOYogpNccHD86O59NyCHWf7sk
2025-03-17 12:52:20,604 - DEBUG - Token recibido: eyJhbGciOiJIUzI1NiIsInR5cCI6IkpXVCJ9.eyJ1c2VyX2lkIjoxfQ.Ql2z3Q06DCptkiE0oobOYogpNccHD86O59NyCHWf7sk
2025-03-17 12:52:20,604 - DEBUG - Token decodificado correctamente, user_id: 1
2025-03-17 12:52:20,604 - DEBUG - Sesión configurada para el usuario: 1
2025-03-17 12:52:21,013 - DEBUG - Verificando permisos para el usuario: None
2025-03-17 12:52:21,013 - DEBUG - Usuario no autenticado: session.get('user_id') devolvió None
2025-03-17 12:52:21,583 - DEBUG - Verificando permisos para el usuario: None
2025-03-17 12:52:21,583 - DEBUG - Usuario no autenticado: session.get('user_id') devolvió None
2025-03-17 12:52:21,765 - DEBUG - Verificando permisos para el usuario: None
2025-03-17 12:52:21,766 - DEBUG - Usuario no autenticado: session.get('user_id') devolvió None
2025-03-17 13:21:10,248 - INFO - 🔧 Backend Flask iniciado.
2025-03-17 13:21:26,355 - INFO - 🔧 Backend Flask iniciado.
2025-03-17 13:21:26,429 - WARNING - Exception raised while handling cache file '/opt/shelly_monitoring/flask_session/2029240f6d1128be89ddc32729463129'
Traceback (most recent call last):
  File "/opt/shelly_monitoring/venv/lib/python3.12/site-packages/cachelib/file.py", line 260, in set
    fd, tmp = tempfile.mkstemp(
              ^^^^^^^^^^^^^^^^^
  File "/usr/lib/python3.12/tempfile.py", line 496, in mkstemp
    return _mkstemp_inner(dir, prefix, suffix, flags, output_type)
           ^^^^^^^^^^^^^^^^^^^^^^^^^^^^^^^^^^^^^^^^^^^^^^^^^^^^^^^
  File "/usr/lib/python3.12/tempfile.py", line 395, in _mkstemp_inner
    fd = _os.open(file, flags, 0o600)
         ^^^^^^^^^^^^^^^^^^^^^^^^^^^^
  File "/opt/shelly_monitoring/venv/lib/python3.12/site-packages/eventlet/green/os.py", line 131, in open
    fd = __original_open__(file, flags, mode)
         ^^^^^^^^^^^^^^^^^^^^^^^^^^^^^^^^^^^^
PermissionError: [Errno 13] Permission denied: '/opt/shelly_monitoring/flask_session/tmpx5nmmnps.__wz_cache'
2025-03-17 13:22:34,037 - DEBUG - Intento de inicio de sesión: admin@shelly.local
2025-03-17 13:22:34,048 - DEBUG - Usuario encontrado en la base de datos
2025-03-17 13:22:34,390 - DEBUG - Contraseña correcta
2025-03-17 13:22:34,390 - DEBUG - Token generado: eyJhbGciOiJIUzI1NiIsInR5cCI6IkpXVCJ9.eyJ1c2VyX2lkIjoxfQ.Ql2z3Q06DCptkiE0oobOYogpNccHD86O59NyCHWf7sk
2025-03-17 13:22:34,391 - WARNING - Exception raised while handling cache file '/opt/shelly_monitoring/flask_session/2029240f6d1128be89ddc32729463129'
Traceback (most recent call last):
  File "/opt/shelly_monitoring/venv/lib/python3.12/site-packages/cachelib/file.py", line 221, in get
    with self._safe_stream_open(filename, "rb") as f:
  File "/usr/lib/python3.12/contextlib.py", line 137, in __enter__
    return next(self.gen)
           ^^^^^^^^^^^^^^
  File "/opt/shelly_monitoring/venv/lib/python3.12/site-packages/cachelib/file.py", line 342, in _safe_stream_open
    fs = self._run_safely(open, path, mode)
         ^^^^^^^^^^^^^^^^^^^^^^^^^^^^^^^^^^
  File "/opt/shelly_monitoring/venv/lib/python3.12/site-packages/cachelib/file.py", line 336, in _run_safely
    output = fn(*args, **kwargs)
             ^^^^^^^^^^^^^^^^^^^
PermissionError: [Errno 13] Permission denied: '/opt/shelly_monitoring/flask_session/2029240f6d1128be89ddc32729463129'
2025-03-17 13:22:34,392 - WARNING - Exception raised while handling cache file '/opt/shelly_monitoring/flask_session/2029240f6d1128be89ddc32729463129'
Traceback (most recent call last):
  File "/opt/shelly_monitoring/venv/lib/python3.12/site-packages/cachelib/file.py", line 221, in get
    with self._safe_stream_open(filename, "rb") as f:
  File "/usr/lib/python3.12/contextlib.py", line 137, in __enter__
    return next(self.gen)
           ^^^^^^^^^^^^^^
  File "/opt/shelly_monitoring/venv/lib/python3.12/site-packages/cachelib/file.py", line 342, in _safe_stream_open
    fs = self._run_safely(open, path, mode)
         ^^^^^^^^^^^^^^^^^^^^^^^^^^^^^^^^^^
  File "/opt/shelly_monitoring/venv/lib/python3.12/site-packages/cachelib/file.py", line 336, in _run_safely
    output = fn(*args, **kwargs)
             ^^^^^^^^^^^^^^^^^^^
PermissionError: [Errno 13] Permission denied: '/opt/shelly_monitoring/flask_session/2029240f6d1128be89ddc32729463129'
2025-03-17 13:22:34,393 - WARNING - Exception raised while handling cache file '/opt/shelly_monitoring/flask_session/acc4c0301d93f214b1c057e114cddef0'
Traceback (most recent call last):
  File "/opt/shelly_monitoring/venv/lib/python3.12/site-packages/cachelib/file.py", line 260, in set
    fd, tmp = tempfile.mkstemp(
              ^^^^^^^^^^^^^^^^^
  File "/usr/lib/python3.12/tempfile.py", line 496, in mkstemp
    return _mkstemp_inner(dir, prefix, suffix, flags, output_type)
           ^^^^^^^^^^^^^^^^^^^^^^^^^^^^^^^^^^^^^^^^^^^^^^^^^^^^^^^
  File "/usr/lib/python3.12/tempfile.py", line 395, in _mkstemp_inner
    fd = _os.open(file, flags, 0o600)
         ^^^^^^^^^^^^^^^^^^^^^^^^^^^^
  File "/opt/shelly_monitoring/venv/lib/python3.12/site-packages/eventlet/green/os.py", line 131, in open
    fd = __original_open__(file, flags, mode)
         ^^^^^^^^^^^^^^^^^^^^^^^^^^^^^^^^^^^^
PermissionError: [Errno 13] Permission denied: '/opt/shelly_monitoring/flask_session/tmpo07r3d32.__wz_cache'
2025-03-17 13:22:35,092 - DEBUG - Ejecutando middleware require_login
2025-03-17 13:22:35,092 - DEBUG - Authorization header: Bearer eyJhbGciOiJIUzI1NiIsInR5cCI6IkpXVCJ9.eyJ1c2VyX2lkIjoxfQ.Ql2z3Q06DCptkiE0oobOYogpNccHD86O59NyCHWf7sk
2025-03-17 13:22:35,092 - DEBUG - Token recibido: eyJhbGciOiJIUzI1NiIsInR5cCI6IkpXVCJ9.eyJ1c2VyX2lkIjoxfQ.Ql2z3Q06DCptkiE0oobOYogpNccHD86O59NyCHWf7sk
2025-03-17 13:22:35,093 - DEBUG - Token decodificado correctamente, user_id: 1
2025-03-17 13:22:35,093 - DEBUG - Sesión configurada para el usuario: 1
2025-03-17 13:22:35,093 - WARNING - Exception raised while handling cache file '/opt/shelly_monitoring/flask_session/2029240f6d1128be89ddc32729463129'
Traceback (most recent call last):
  File "/opt/shelly_monitoring/venv/lib/python3.12/site-packages/cachelib/file.py", line 221, in get
    with self._safe_stream_open(filename, "rb") as f:
  File "/usr/lib/python3.12/contextlib.py", line 137, in __enter__
    return next(self.gen)
           ^^^^^^^^^^^^^^
  File "/opt/shelly_monitoring/venv/lib/python3.12/site-packages/cachelib/file.py", line 342, in _safe_stream_open
    fs = self._run_safely(open, path, mode)
         ^^^^^^^^^^^^^^^^^^^^^^^^^^^^^^^^^^
  File "/opt/shelly_monitoring/venv/lib/python3.12/site-packages/cachelib/file.py", line 336, in _run_safely
    output = fn(*args, **kwargs)
             ^^^^^^^^^^^^^^^^^^^
PermissionError: [Errno 13] Permission denied: '/opt/shelly_monitoring/flask_session/2029240f6d1128be89ddc32729463129'
2025-03-17 13:22:35,094 - WARNING - Exception raised while handling cache file '/opt/shelly_monitoring/flask_session/2029240f6d1128be89ddc32729463129'
Traceback (most recent call last):
  File "/opt/shelly_monitoring/venv/lib/python3.12/site-packages/cachelib/file.py", line 221, in get
    with self._safe_stream_open(filename, "rb") as f:
  File "/usr/lib/python3.12/contextlib.py", line 137, in __enter__
    return next(self.gen)
           ^^^^^^^^^^^^^^
  File "/opt/shelly_monitoring/venv/lib/python3.12/site-packages/cachelib/file.py", line 342, in _safe_stream_open
    fs = self._run_safely(open, path, mode)
         ^^^^^^^^^^^^^^^^^^^^^^^^^^^^^^^^^^
  File "/opt/shelly_monitoring/venv/lib/python3.12/site-packages/cachelib/file.py", line 336, in _run_safely
    output = fn(*args, **kwargs)
             ^^^^^^^^^^^^^^^^^^^
PermissionError: [Errno 13] Permission denied: '/opt/shelly_monitoring/flask_session/2029240f6d1128be89ddc32729463129'
2025-03-17 13:22:35,094 - WARNING - Exception raised while handling cache file '/opt/shelly_monitoring/flask_session/4116d5c6ffac814eee94635568225e2c'
Traceback (most recent call last):
  File "/opt/shelly_monitoring/venv/lib/python3.12/site-packages/cachelib/file.py", line 260, in set
    fd, tmp = tempfile.mkstemp(
              ^^^^^^^^^^^^^^^^^
  File "/usr/lib/python3.12/tempfile.py", line 496, in mkstemp
    return _mkstemp_inner(dir, prefix, suffix, flags, output_type)
           ^^^^^^^^^^^^^^^^^^^^^^^^^^^^^^^^^^^^^^^^^^^^^^^^^^^^^^^
  File "/usr/lib/python3.12/tempfile.py", line 395, in _mkstemp_inner
    fd = _os.open(file, flags, 0o600)
         ^^^^^^^^^^^^^^^^^^^^^^^^^^^^
  File "/opt/shelly_monitoring/venv/lib/python3.12/site-packages/eventlet/green/os.py", line 131, in open
    fd = __original_open__(file, flags, mode)
         ^^^^^^^^^^^^^^^^^^^^^^^^^^^^^^^^^^^^
PermissionError: [Errno 13] Permission denied: '/opt/shelly_monitoring/flask_session/tmpx1nknzdb.__wz_cache'
2025-03-17 13:22:35,565 - DEBUG - Verificando permisos para el usuario: None
2025-03-17 13:22:35,566 - DEBUG - Usuario no autenticado: session.get('user_id') devolvió None
2025-03-17 13:22:36,162 - DEBUG - Verificando permisos para el usuario: None
2025-03-17 13:22:36,162 - DEBUG - Usuario no autenticado: session.get('user_id') devolvió None
2025-03-17 13:22:36,334 - DEBUG - Verificando permisos para el usuario: None
2025-03-17 13:22:36,334 - DEBUG - Usuario no autenticado: session.get('user_id') devolvió None
2025-03-17 19:38:26,225 - DEBUG - Intento de inicio de sesión: admin@shelly.local
2025-03-17 19:38:26,230 - DEBUG - Usuario encontrado en la base de datos
2025-03-17 19:38:26,569 - DEBUG - Contraseña correcta
2025-03-17 19:38:26,569 - DEBUG - Token generado: eyJhbGciOiJIUzI1NiIsInR5cCI6IkpXVCJ9.eyJ1c2VyX2lkIjoxfQ.Ql2z3Q06DCptkiE0oobOYogpNccHD86O59NyCHWf7sk
2025-03-17 19:38:26,570 - WARNING - Exception raised while handling cache file '/opt/shelly_monitoring/flask_session/2029240f6d1128be89ddc32729463129'
Traceback (most recent call last):
  File "/opt/shelly_monitoring/venv/lib/python3.12/site-packages/cachelib/file.py", line 221, in get
    with self._safe_stream_open(filename, "rb") as f:
  File "/usr/lib/python3.12/contextlib.py", line 137, in __enter__
    return next(self.gen)
           ^^^^^^^^^^^^^^
  File "/opt/shelly_monitoring/venv/lib/python3.12/site-packages/cachelib/file.py", line 342, in _safe_stream_open
    fs = self._run_safely(open, path, mode)
         ^^^^^^^^^^^^^^^^^^^^^^^^^^^^^^^^^^
  File "/opt/shelly_monitoring/venv/lib/python3.12/site-packages/cachelib/file.py", line 336, in _run_safely
    output = fn(*args, **kwargs)
             ^^^^^^^^^^^^^^^^^^^
PermissionError: [Errno 13] Permission denied: '/opt/shelly_monitoring/flask_session/2029240f6d1128be89ddc32729463129'
2025-03-17 19:38:26,571 - WARNING - Exception raised while handling cache file '/opt/shelly_monitoring/flask_session/2029240f6d1128be89ddc32729463129'
Traceback (most recent call last):
  File "/opt/shelly_monitoring/venv/lib/python3.12/site-packages/cachelib/file.py", line 221, in get
    with self._safe_stream_open(filename, "rb") as f:
  File "/usr/lib/python3.12/contextlib.py", line 137, in __enter__
    return next(self.gen)
           ^^^^^^^^^^^^^^
  File "/opt/shelly_monitoring/venv/lib/python3.12/site-packages/cachelib/file.py", line 342, in _safe_stream_open
    fs = self._run_safely(open, path, mode)
         ^^^^^^^^^^^^^^^^^^^^^^^^^^^^^^^^^^
  File "/opt/shelly_monitoring/venv/lib/python3.12/site-packages/cachelib/file.py", line 336, in _run_safely
    output = fn(*args, **kwargs)
             ^^^^^^^^^^^^^^^^^^^
PermissionError: [Errno 13] Permission denied: '/opt/shelly_monitoring/flask_session/2029240f6d1128be89ddc32729463129'
2025-03-17 19:38:26,571 - WARNING - Exception raised while handling cache file '/opt/shelly_monitoring/flask_session/814d22f28b7ae73ec71f79e9be117f0a'
Traceback (most recent call last):
  File "/opt/shelly_monitoring/venv/lib/python3.12/site-packages/cachelib/file.py", line 260, in set
    fd, tmp = tempfile.mkstemp(
              ^^^^^^^^^^^^^^^^^
  File "/usr/lib/python3.12/tempfile.py", line 496, in mkstemp
    return _mkstemp_inner(dir, prefix, suffix, flags, output_type)
           ^^^^^^^^^^^^^^^^^^^^^^^^^^^^^^^^^^^^^^^^^^^^^^^^^^^^^^^
  File "/usr/lib/python3.12/tempfile.py", line 395, in _mkstemp_inner
    fd = _os.open(file, flags, 0o600)
         ^^^^^^^^^^^^^^^^^^^^^^^^^^^^
  File "/opt/shelly_monitoring/venv/lib/python3.12/site-packages/eventlet/green/os.py", line 131, in open
    fd = __original_open__(file, flags, mode)
         ^^^^^^^^^^^^^^^^^^^^^^^^^^^^^^^^^^^^
PermissionError: [Errno 13] Permission denied: '/opt/shelly_monitoring/flask_session/tmpzd8kst2y.__wz_cache'
2025-03-17 19:38:27,091 - DEBUG - Ejecutando middleware require_login
2025-03-17 19:38:27,091 - DEBUG - Authorization header: Bearer eyJhbGciOiJIUzI1NiIsInR5cCI6IkpXVCJ9.eyJ1c2VyX2lkIjoxfQ.Ql2z3Q06DCptkiE0oobOYogpNccHD86O59NyCHWf7sk
2025-03-17 19:38:27,091 - DEBUG - Token recibido: eyJhbGciOiJIUzI1NiIsInR5cCI6IkpXVCJ9.eyJ1c2VyX2lkIjoxfQ.Ql2z3Q06DCptkiE0oobOYogpNccHD86O59NyCHWf7sk
2025-03-17 19:38:27,091 - DEBUG - Token decodificado correctamente, user_id: 1
2025-03-17 19:38:27,091 - DEBUG - Sesión configurada para el usuario: 1
2025-03-17 19:38:27,092 - WARNING - Exception raised while handling cache file '/opt/shelly_monitoring/flask_session/2029240f6d1128be89ddc32729463129'
Traceback (most recent call last):
  File "/opt/shelly_monitoring/venv/lib/python3.12/site-packages/cachelib/file.py", line 221, in get
    with self._safe_stream_open(filename, "rb") as f:
  File "/usr/lib/python3.12/contextlib.py", line 137, in __enter__
    return next(self.gen)
           ^^^^^^^^^^^^^^
  File "/opt/shelly_monitoring/venv/lib/python3.12/site-packages/cachelib/file.py", line 342, in _safe_stream_open
    fs = self._run_safely(open, path, mode)
         ^^^^^^^^^^^^^^^^^^^^^^^^^^^^^^^^^^
  File "/opt/shelly_monitoring/venv/lib/python3.12/site-packages/cachelib/file.py", line 336, in _run_safely
    output = fn(*args, **kwargs)
             ^^^^^^^^^^^^^^^^^^^
PermissionError: [Errno 13] Permission denied: '/opt/shelly_monitoring/flask_session/2029240f6d1128be89ddc32729463129'
2025-03-17 19:38:27,092 - WARNING - Exception raised while handling cache file '/opt/shelly_monitoring/flask_session/2029240f6d1128be89ddc32729463129'
Traceback (most recent call last):
  File "/opt/shelly_monitoring/venv/lib/python3.12/site-packages/cachelib/file.py", line 221, in get
    with self._safe_stream_open(filename, "rb") as f:
  File "/usr/lib/python3.12/contextlib.py", line 137, in __enter__
    return next(self.gen)
           ^^^^^^^^^^^^^^
  File "/opt/shelly_monitoring/venv/lib/python3.12/site-packages/cachelib/file.py", line 342, in _safe_stream_open
    fs = self._run_safely(open, path, mode)
         ^^^^^^^^^^^^^^^^^^^^^^^^^^^^^^^^^^
  File "/opt/shelly_monitoring/venv/lib/python3.12/site-packages/cachelib/file.py", line 336, in _run_safely
    output = fn(*args, **kwargs)
             ^^^^^^^^^^^^^^^^^^^
PermissionError: [Errno 13] Permission denied: '/opt/shelly_monitoring/flask_session/2029240f6d1128be89ddc32729463129'
2025-03-17 19:38:27,093 - WARNING - Exception raised while handling cache file '/opt/shelly_monitoring/flask_session/6bc69ae34c994156aa7d443180391dec'
Traceback (most recent call last):
  File "/opt/shelly_monitoring/venv/lib/python3.12/site-packages/cachelib/file.py", line 260, in set
    fd, tmp = tempfile.mkstemp(
              ^^^^^^^^^^^^^^^^^
  File "/usr/lib/python3.12/tempfile.py", line 496, in mkstemp
    return _mkstemp_inner(dir, prefix, suffix, flags, output_type)
           ^^^^^^^^^^^^^^^^^^^^^^^^^^^^^^^^^^^^^^^^^^^^^^^^^^^^^^^
  File "/usr/lib/python3.12/tempfile.py", line 395, in _mkstemp_inner
    fd = _os.open(file, flags, 0o600)
         ^^^^^^^^^^^^^^^^^^^^^^^^^^^^
  File "/opt/shelly_monitoring/venv/lib/python3.12/site-packages/eventlet/green/os.py", line 131, in open
    fd = __original_open__(file, flags, mode)
         ^^^^^^^^^^^^^^^^^^^^^^^^^^^^^^^^^^^^
PermissionError: [Errno 13] Permission denied: '/opt/shelly_monitoring/flask_session/tmphh7o4e5k.__wz_cache'
2025-03-17 19:38:27,517 - DEBUG - Verificando permisos para el usuario: None
2025-03-17 19:38:27,517 - DEBUG - Usuario no autenticado: session.get('user_id') devolvió None
2025-03-17 19:38:28,112 - DEBUG - Verificando permisos para el usuario: None
2025-03-17 19:38:28,112 - DEBUG - Usuario no autenticado: session.get('user_id') devolvió None
2025-03-17 19:38:28,296 - DEBUG - Verificando permisos para el usuario: None
2025-03-17 19:38:28,296 - DEBUG - Usuario no autenticado: session.get('user_id') devolvió None
2025-03-17 19:43:21,618 - INFO - 🔧 Backend Flask iniciado.
2025-03-17 19:43:21,674 - WARNING - Exception raised while handling cache file '/opt/shelly_monitoring/flask_session/2029240f6d1128be89ddc32729463129'
Traceback (most recent call last):
  File "/opt/shelly_monitoring/venv/lib/python3.12/site-packages/cachelib/file.py", line 260, in set
    fd, tmp = tempfile.mkstemp(
              ^^^^^^^^^^^^^^^^^
  File "/usr/lib/python3.12/tempfile.py", line 496, in mkstemp
    return _mkstemp_inner(dir, prefix, suffix, flags, output_type)
           ^^^^^^^^^^^^^^^^^^^^^^^^^^^^^^^^^^^^^^^^^^^^^^^^^^^^^^^
  File "/usr/lib/python3.12/tempfile.py", line 395, in _mkstemp_inner
    fd = _os.open(file, flags, 0o600)
         ^^^^^^^^^^^^^^^^^^^^^^^^^^^^
  File "/opt/shelly_monitoring/venv/lib/python3.12/site-packages/eventlet/green/os.py", line 131, in open
    fd = __original_open__(file, flags, mode)
         ^^^^^^^^^^^^^^^^^^^^^^^^^^^^^^^^^^^^
PermissionError: [Errno 13] Permission denied: '/opt/shelly_monitoring/flask_session/tmpv3kd7m7i.__wz_cache'
2025-03-17 19:44:21,231 - DEBUG - Intento de inicio de sesión: admin@shelly.local
2025-03-17 19:44:21,242 - DEBUG - Usuario encontrado en la base de datos
2025-03-17 19:44:21,584 - DEBUG - Contraseña correcta
2025-03-17 19:44:21,584 - DEBUG - Token generado: eyJhbGciOiJIUzI1NiIsInR5cCI6IkpXVCJ9.eyJ1c2VyX2lkIjoxfQ.Ql2z3Q06DCptkiE0oobOYogpNccHD86O59NyCHWf7sk
2025-03-17 19:44:21,585 - WARNING - Exception raised while handling cache file '/opt/shelly_monitoring/flask_session/2029240f6d1128be89ddc32729463129'
Traceback (most recent call last):
  File "/opt/shelly_monitoring/venv/lib/python3.12/site-packages/cachelib/file.py", line 221, in get
    with self._safe_stream_open(filename, "rb") as f:
  File "/usr/lib/python3.12/contextlib.py", line 137, in __enter__
    return next(self.gen)
           ^^^^^^^^^^^^^^
  File "/opt/shelly_monitoring/venv/lib/python3.12/site-packages/cachelib/file.py", line 342, in _safe_stream_open
    fs = self._run_safely(open, path, mode)
         ^^^^^^^^^^^^^^^^^^^^^^^^^^^^^^^^^^
  File "/opt/shelly_monitoring/venv/lib/python3.12/site-packages/cachelib/file.py", line 336, in _run_safely
    output = fn(*args, **kwargs)
             ^^^^^^^^^^^^^^^^^^^
PermissionError: [Errno 13] Permission denied: '/opt/shelly_monitoring/flask_session/2029240f6d1128be89ddc32729463129'
2025-03-17 19:44:21,586 - WARNING - Exception raised while handling cache file '/opt/shelly_monitoring/flask_session/2029240f6d1128be89ddc32729463129'
Traceback (most recent call last):
  File "/opt/shelly_monitoring/venv/lib/python3.12/site-packages/cachelib/file.py", line 221, in get
    with self._safe_stream_open(filename, "rb") as f:
  File "/usr/lib/python3.12/contextlib.py", line 137, in __enter__
    return next(self.gen)
           ^^^^^^^^^^^^^^
  File "/opt/shelly_monitoring/venv/lib/python3.12/site-packages/cachelib/file.py", line 342, in _safe_stream_open
    fs = self._run_safely(open, path, mode)
         ^^^^^^^^^^^^^^^^^^^^^^^^^^^^^^^^^^
  File "/opt/shelly_monitoring/venv/lib/python3.12/site-packages/cachelib/file.py", line 336, in _run_safely
    output = fn(*args, **kwargs)
             ^^^^^^^^^^^^^^^^^^^
PermissionError: [Errno 13] Permission denied: '/opt/shelly_monitoring/flask_session/2029240f6d1128be89ddc32729463129'
2025-03-17 19:44:21,587 - WARNING - Exception raised while handling cache file '/opt/shelly_monitoring/flask_session/d816eb30fab354e05881b6504abacdf1'
Traceback (most recent call last):
  File "/opt/shelly_monitoring/venv/lib/python3.12/site-packages/cachelib/file.py", line 260, in set
    fd, tmp = tempfile.mkstemp(
              ^^^^^^^^^^^^^^^^^
  File "/usr/lib/python3.12/tempfile.py", line 496, in mkstemp
    return _mkstemp_inner(dir, prefix, suffix, flags, output_type)
           ^^^^^^^^^^^^^^^^^^^^^^^^^^^^^^^^^^^^^^^^^^^^^^^^^^^^^^^
  File "/usr/lib/python3.12/tempfile.py", line 395, in _mkstemp_inner
    fd = _os.open(file, flags, 0o600)
         ^^^^^^^^^^^^^^^^^^^^^^^^^^^^
  File "/opt/shelly_monitoring/venv/lib/python3.12/site-packages/eventlet/green/os.py", line 131, in open
    fd = __original_open__(file, flags, mode)
         ^^^^^^^^^^^^^^^^^^^^^^^^^^^^^^^^^^^^
PermissionError: [Errno 13] Permission denied: '/opt/shelly_monitoring/flask_session/tmp62rxiy71.__wz_cache'
2025-03-17 19:44:22,279 - DEBUG - Ejecutando middleware require_login
2025-03-17 19:44:22,279 - DEBUG - Authorization header: Bearer eyJhbGciOiJIUzI1NiIsInR5cCI6IkpXVCJ9.eyJ1c2VyX2lkIjoxfQ.Ql2z3Q06DCptkiE0oobOYogpNccHD86O59NyCHWf7sk
2025-03-17 19:44:22,279 - DEBUG - Token recibido: eyJhbGciOiJIUzI1NiIsInR5cCI6IkpXVCJ9.eyJ1c2VyX2lkIjoxfQ.Ql2z3Q06DCptkiE0oobOYogpNccHD86O59NyCHWf7sk
2025-03-17 19:44:22,279 - DEBUG - Token decodificado correctamente, user_id: 1
2025-03-17 19:44:22,279 - DEBUG - Sesión configurada para el usuario: 1
2025-03-17 19:44:22,280 - WARNING - Exception raised while handling cache file '/opt/shelly_monitoring/flask_session/2029240f6d1128be89ddc32729463129'
Traceback (most recent call last):
  File "/opt/shelly_monitoring/venv/lib/python3.12/site-packages/cachelib/file.py", line 221, in get
    with self._safe_stream_open(filename, "rb") as f:
  File "/usr/lib/python3.12/contextlib.py", line 137, in __enter__
    return next(self.gen)
           ^^^^^^^^^^^^^^
  File "/opt/shelly_monitoring/venv/lib/python3.12/site-packages/cachelib/file.py", line 342, in _safe_stream_open
    fs = self._run_safely(open, path, mode)
         ^^^^^^^^^^^^^^^^^^^^^^^^^^^^^^^^^^
  File "/opt/shelly_monitoring/venv/lib/python3.12/site-packages/cachelib/file.py", line 336, in _run_safely
    output = fn(*args, **kwargs)
             ^^^^^^^^^^^^^^^^^^^
PermissionError: [Errno 13] Permission denied: '/opt/shelly_monitoring/flask_session/2029240f6d1128be89ddc32729463129'
2025-03-17 19:44:22,280 - WARNING - Exception raised while handling cache file '/opt/shelly_monitoring/flask_session/2029240f6d1128be89ddc32729463129'
Traceback (most recent call last):
  File "/opt/shelly_monitoring/venv/lib/python3.12/site-packages/cachelib/file.py", line 221, in get
    with self._safe_stream_open(filename, "rb") as f:
  File "/usr/lib/python3.12/contextlib.py", line 137, in __enter__
    return next(self.gen)
           ^^^^^^^^^^^^^^
  File "/opt/shelly_monitoring/venv/lib/python3.12/site-packages/cachelib/file.py", line 342, in _safe_stream_open
    fs = self._run_safely(open, path, mode)
         ^^^^^^^^^^^^^^^^^^^^^^^^^^^^^^^^^^
  File "/opt/shelly_monitoring/venv/lib/python3.12/site-packages/cachelib/file.py", line 336, in _run_safely
    output = fn(*args, **kwargs)
             ^^^^^^^^^^^^^^^^^^^
PermissionError: [Errno 13] Permission denied: '/opt/shelly_monitoring/flask_session/2029240f6d1128be89ddc32729463129'
2025-03-17 19:44:22,281 - WARNING - Exception raised while handling cache file '/opt/shelly_monitoring/flask_session/b3fee8a128316daa74274b8126c861bd'
Traceback (most recent call last):
  File "/opt/shelly_monitoring/venv/lib/python3.12/site-packages/cachelib/file.py", line 260, in set
    fd, tmp = tempfile.mkstemp(
              ^^^^^^^^^^^^^^^^^
  File "/usr/lib/python3.12/tempfile.py", line 496, in mkstemp
    return _mkstemp_inner(dir, prefix, suffix, flags, output_type)
           ^^^^^^^^^^^^^^^^^^^^^^^^^^^^^^^^^^^^^^^^^^^^^^^^^^^^^^^
  File "/usr/lib/python3.12/tempfile.py", line 395, in _mkstemp_inner
    fd = _os.open(file, flags, 0o600)
         ^^^^^^^^^^^^^^^^^^^^^^^^^^^^
  File "/opt/shelly_monitoring/venv/lib/python3.12/site-packages/eventlet/green/os.py", line 131, in open
    fd = __original_open__(file, flags, mode)
         ^^^^^^^^^^^^^^^^^^^^^^^^^^^^^^^^^^^^
PermissionError: [Errno 13] Permission denied: '/opt/shelly_monitoring/flask_session/tmpm1siah92.__wz_cache'
2025-03-17 19:44:22,835 - DEBUG - Verificando permisos para el usuario: None
2025-03-17 19:44:22,835 - DEBUG - Usuario no autenticado: session.get('user_id') devolvió None
2025-03-17 19:44:23,336 - DEBUG - Verificando permisos para el usuario: None
2025-03-17 19:44:23,336 - DEBUG - Usuario no autenticado: session.get('user_id') devolvió None
2025-03-17 19:44:23,475 - DEBUG - Verificando permisos para el usuario: None
2025-03-17 19:44:23,475 - DEBUG - Usuario no autenticado: session.get('user_id') devolvió None
2025-03-17 19:49:29,829 - INFO - 🔧 Backend Flask iniciado.
2025-03-17 19:49:29,886 - WARNING - Exception raised while handling cache file '/opt/shelly_monitoring/flask_session/2029240f6d1128be89ddc32729463129'
Traceback (most recent call last):
  File "/opt/shelly_monitoring/venv/lib/python3.12/site-packages/cachelib/file.py", line 260, in set
    fd, tmp = tempfile.mkstemp(
              ^^^^^^^^^^^^^^^^^
  File "/usr/lib/python3.12/tempfile.py", line 496, in mkstemp
    return _mkstemp_inner(dir, prefix, suffix, flags, output_type)
           ^^^^^^^^^^^^^^^^^^^^^^^^^^^^^^^^^^^^^^^^^^^^^^^^^^^^^^^
  File "/usr/lib/python3.12/tempfile.py", line 395, in _mkstemp_inner
    fd = _os.open(file, flags, 0o600)
         ^^^^^^^^^^^^^^^^^^^^^^^^^^^^
  File "/opt/shelly_monitoring/venv/lib/python3.12/site-packages/eventlet/green/os.py", line 131, in open
    fd = __original_open__(file, flags, mode)
         ^^^^^^^^^^^^^^^^^^^^^^^^^^^^^^^^^^^^
PermissionError: [Errno 13] Permission denied: '/opt/shelly_monitoring/flask_session/tmpo9bmkghz.__wz_cache'
2025-03-17 19:50:32,098 - INFO - 🔧 Backend Flask iniciado.
2025-03-17 19:50:59,929 - DEBUG - Intento de inicio de sesión: admin@shelly.local
2025-03-17 19:50:59,939 - DEBUG - Usuario encontrado en la base de datos
2025-03-17 19:51:00,279 - DEBUG - Contraseña correcta
2025-03-17 19:51:00,279 - DEBUG - Token generado: eyJhbGciOiJIUzI1NiIsInR5cCI6IkpXVCJ9.eyJ1c2VyX2lkIjoxfQ.Ql2z3Q06DCptkiE0oobOYogpNccHD86O59NyCHWf7sk
2025-03-17 19:51:00,564 - DEBUG - Ejecutando middleware require_login
2025-03-17 19:51:00,564 - DEBUG - Authorization header: Bearer eyJhbGciOiJIUzI1NiIsInR5cCI6IkpXVCJ9.eyJ1c2VyX2lkIjoxfQ.Ql2z3Q06DCptkiE0oobOYogpNccHD86O59NyCHWf7sk
2025-03-17 19:51:00,564 - DEBUG - Token recibido: eyJhbGciOiJIUzI1NiIsInR5cCI6IkpXVCJ9.eyJ1c2VyX2lkIjoxfQ.Ql2z3Q06DCptkiE0oobOYogpNccHD86O59NyCHWf7sk
2025-03-17 19:51:00,565 - DEBUG - Token decodificado correctamente, user_id: 1
2025-03-17 19:51:00,565 - DEBUG - Sesión configurada para el usuario: 1
2025-03-17 19:51:00,864 - DEBUG - Verificando permisos para el usuario: None
2025-03-17 19:51:00,864 - DEBUG - Usuario no autenticado: session.get('user_id') devolvió None
2025-03-17 19:51:01,197 - DEBUG - Verificando permisos para el usuario: None
2025-03-17 19:51:01,197 - DEBUG - Usuario no autenticado: session.get('user_id') devolvió None
2025-03-17 19:51:01,198 - DEBUG - Verificando permisos para el usuario: None
2025-03-17 19:51:01,198 - DEBUG - Usuario no autenticado: session.get('user_id') devolvió None
2025-03-17 19:54:47,556 - INFO - 🔧 Backend Flask iniciado.
2025-03-17 19:55:08,697 - DEBUG - Intento de inicio de sesión: admin@shelly.local
2025-03-17 19:55:08,710 - DEBUG - Usuario encontrado en la base de datos
2025-03-17 19:55:09,050 - DEBUG - Contraseña correcta
2025-03-17 19:55:09,050 - DEBUG - Token generado: eyJhbGciOiJIUzI1NiIsInR5cCI6IkpXVCJ9.eyJ1c2VyX2lkIjoxfQ.Ql2z3Q06DCptkiE0oobOYogpNccHD86O59NyCHWf7sk
2025-03-17 19:55:09,537 - DEBUG - Ejecutando middleware require_login
2025-03-17 19:55:09,538 - DEBUG - Authorization header: Bearer eyJhbGciOiJIUzI1NiIsInR5cCI6IkpXVCJ9.eyJ1c2VyX2lkIjoxfQ.Ql2z3Q06DCptkiE0oobOYogpNccHD86O59NyCHWf7sk
2025-03-17 19:55:09,538 - DEBUG - Token recibido: eyJhbGciOiJIUzI1NiIsInR5cCI6IkpXVCJ9.eyJ1c2VyX2lkIjoxfQ.Ql2z3Q06DCptkiE0oobOYogpNccHD86O59NyCHWf7sk
2025-03-17 19:55:09,538 - DEBUG - Token decodificado correctamente, user_id: 1
2025-03-17 19:55:09,538 - DEBUG - Sesión configurada para el usuario: 1
2025-03-17 19:55:09,538 - ERROR - Exception on /api/roles/admin/permissions [GET]
Traceback (most recent call last):
  File "/opt/shelly_monitoring/venv/lib/python3.12/site-packages/flask/app.py", line 1511, in wsgi_app
    response = self.full_dispatch_request()
               ^^^^^^^^^^^^^^^^^^^^^^^^^^^^
  File "/opt/shelly_monitoring/venv/lib/python3.12/site-packages/flask/app.py", line 919, in full_dispatch_request
    rv = self.handle_user_exception(e)
         ^^^^^^^^^^^^^^^^^^^^^^^^^^^^^
  File "/opt/shelly_monitoring/venv/lib/python3.12/site-packages/flask_cors/extension.py", line 176, in wrapped_function
    return cors_after_request(app.make_response(f(*args, **kwargs)))
                                                ^^^^^^^^^^^^^^^^^^
  File "/opt/shelly_monitoring/venv/lib/python3.12/site-packages/flask/app.py", line 917, in full_dispatch_request
    rv = self.dispatch_request()
         ^^^^^^^^^^^^^^^^^^^^^^^
  File "/opt/shelly_monitoring/venv/lib/python3.12/site-packages/flask/app.py", line 902, in dispatch_request
    return self.ensure_sync(self.view_functions[rule.endpoint])(**view_args)  # type: ignore[no-any-return]
           ^^^^^^^^^^^^^^^^^^^^^^^^^^^^^^^^^^^^^^^^^^^^^^^^^^^^^^^^^^^^^^^^^
  File "/opt/shelly_monitoring/app.py", line 74, in decorated_function
    session.save()  # Guardar la sesión explícitamente
    ^^^^^^^^^^^^
AttributeError: 'FileSystemSession' object has no attribute 'save'
2025-03-17 19:55:24,371 - DEBUG - Intento de inicio de sesión: admin@shelly.local
2025-03-17 19:55:24,374 - DEBUG - Usuario encontrado en la base de datos
2025-03-17 19:55:24,717 - DEBUG - Contraseña correcta
2025-03-17 19:55:24,719 - DEBUG - Token generado: eyJhbGciOiJIUzI1NiIsInR5cCI6IkpXVCJ9.eyJ1c2VyX2lkIjoxfQ.Ql2z3Q06DCptkiE0oobOYogpNccHD86O59NyCHWf7sk
2025-03-17 19:55:25,005 - DEBUG - Ejecutando middleware require_login
2025-03-17 19:55:25,006 - DEBUG - Authorization header: Bearer eyJhbGciOiJIUzI1NiIsInR5cCI6IkpXVCJ9.eyJ1c2VyX2lkIjoxfQ.Ql2z3Q06DCptkiE0oobOYogpNccHD86O59NyCHWf7sk
2025-03-17 19:55:25,006 - DEBUG - Token recibido: eyJhbGciOiJIUzI1NiIsInR5cCI6IkpXVCJ9.eyJ1c2VyX2lkIjoxfQ.Ql2z3Q06DCptkiE0oobOYogpNccHD86O59NyCHWf7sk
2025-03-17 19:55:25,006 - DEBUG - Token decodificado correctamente, user_id: 1
2025-03-17 19:55:25,006 - DEBUG - Sesión configurada para el usuario: 1
2025-03-17 19:55:25,006 - ERROR - Exception on /api/roles/admin/permissions [GET]
Traceback (most recent call last):
  File "/opt/shelly_monitoring/venv/lib/python3.12/site-packages/flask/app.py", line 1511, in wsgi_app
    response = self.full_dispatch_request()
               ^^^^^^^^^^^^^^^^^^^^^^^^^^^^
  File "/opt/shelly_monitoring/venv/lib/python3.12/site-packages/flask/app.py", line 919, in full_dispatch_request
    rv = self.handle_user_exception(e)
         ^^^^^^^^^^^^^^^^^^^^^^^^^^^^^
  File "/opt/shelly_monitoring/venv/lib/python3.12/site-packages/flask_cors/extension.py", line 176, in wrapped_function
    return cors_after_request(app.make_response(f(*args, **kwargs)))
                                                ^^^^^^^^^^^^^^^^^^
  File "/opt/shelly_monitoring/venv/lib/python3.12/site-packages/flask/app.py", line 917, in full_dispatch_request
    rv = self.dispatch_request()
         ^^^^^^^^^^^^^^^^^^^^^^^
  File "/opt/shelly_monitoring/venv/lib/python3.12/site-packages/flask/app.py", line 902, in dispatch_request
    return self.ensure_sync(self.view_functions[rule.endpoint])(**view_args)  # type: ignore[no-any-return]
           ^^^^^^^^^^^^^^^^^^^^^^^^^^^^^^^^^^^^^^^^^^^^^^^^^^^^^^^^^^^^^^^^^
  File "/opt/shelly_monitoring/app.py", line 74, in decorated_function
    session.save()  # Guardar la sesión explícitamente
    ^^^^^^^^^^^^
AttributeError: 'FileSystemSession' object has no attribute 'save'
2025-03-17 19:55:33,392 - DEBUG - Intento de inicio de sesión: admin@shelly.local
2025-03-17 19:55:33,395 - DEBUG - Usuario encontrado en la base de datos
2025-03-17 19:55:33,734 - DEBUG - Contraseña correcta
2025-03-17 19:55:33,734 - DEBUG - Token generado: eyJhbGciOiJIUzI1NiIsInR5cCI6IkpXVCJ9.eyJ1c2VyX2lkIjoxfQ.Ql2z3Q06DCptkiE0oobOYogpNccHD86O59NyCHWf7sk
2025-03-17 19:55:34,019 - DEBUG - Ejecutando middleware require_login
2025-03-17 19:55:34,019 - DEBUG - Authorization header: Bearer eyJhbGciOiJIUzI1NiIsInR5cCI6IkpXVCJ9.eyJ1c2VyX2lkIjoxfQ.Ql2z3Q06DCptkiE0oobOYogpNccHD86O59NyCHWf7sk
2025-03-17 19:55:34,019 - DEBUG - Token recibido: eyJhbGciOiJIUzI1NiIsInR5cCI6IkpXVCJ9.eyJ1c2VyX2lkIjoxfQ.Ql2z3Q06DCptkiE0oobOYogpNccHD86O59NyCHWf7sk
2025-03-17 19:55:34,019 - DEBUG - Token decodificado correctamente, user_id: 1
2025-03-17 19:55:34,019 - DEBUG - Sesión configurada para el usuario: 1
2025-03-17 19:55:34,020 - ERROR - Exception on /api/roles/admin/permissions [GET]
Traceback (most recent call last):
  File "/opt/shelly_monitoring/venv/lib/python3.12/site-packages/flask/app.py", line 1511, in wsgi_app
    response = self.full_dispatch_request()
               ^^^^^^^^^^^^^^^^^^^^^^^^^^^^
  File "/opt/shelly_monitoring/venv/lib/python3.12/site-packages/flask/app.py", line 919, in full_dispatch_request
    rv = self.handle_user_exception(e)
         ^^^^^^^^^^^^^^^^^^^^^^^^^^^^^
  File "/opt/shelly_monitoring/venv/lib/python3.12/site-packages/flask_cors/extension.py", line 176, in wrapped_function
    return cors_after_request(app.make_response(f(*args, **kwargs)))
                                                ^^^^^^^^^^^^^^^^^^
  File "/opt/shelly_monitoring/venv/lib/python3.12/site-packages/flask/app.py", line 917, in full_dispatch_request
    rv = self.dispatch_request()
         ^^^^^^^^^^^^^^^^^^^^^^^
  File "/opt/shelly_monitoring/venv/lib/python3.12/site-packages/flask/app.py", line 902, in dispatch_request
    return self.ensure_sync(self.view_functions[rule.endpoint])(**view_args)  # type: ignore[no-any-return]
           ^^^^^^^^^^^^^^^^^^^^^^^^^^^^^^^^^^^^^^^^^^^^^^^^^^^^^^^^^^^^^^^^^
  File "/opt/shelly_monitoring/app.py", line 74, in decorated_function
    session.save()  # Guardar la sesión explícitamente
    ^^^^^^^^^^^^
AttributeError: 'FileSystemSession' object has no attribute 'save'
2025-03-17 19:57:08,010 - INFO - 🔧 Backend Flask iniciado.
2025-03-17 19:57:23,467 - DEBUG - Intento de inicio de sesión: admin@shelly.local
2025-03-17 19:57:23,476 - DEBUG - Usuario encontrado en la base de datos
2025-03-17 19:57:23,815 - DEBUG - Contraseña correcta
2025-03-17 19:57:23,815 - DEBUG - Token generado: eyJhbGciOiJIUzI1NiIsInR5cCI6IkpXVCJ9.eyJ1c2VyX2lkIjoxfQ.Ql2z3Q06DCptkiE0oobOYogpNccHD86O59NyCHWf7sk
2025-03-17 19:57:24,124 - DEBUG - Ejecutando middleware require_login
2025-03-17 19:57:24,124 - DEBUG - Authorization header: Bearer eyJhbGciOiJIUzI1NiIsInR5cCI6IkpXVCJ9.eyJ1c2VyX2lkIjoxfQ.Ql2z3Q06DCptkiE0oobOYogpNccHD86O59NyCHWf7sk
2025-03-17 19:57:24,125 - DEBUG - Token recibido: eyJhbGciOiJIUzI1NiIsInR5cCI6IkpXVCJ9.eyJ1c2VyX2lkIjoxfQ.Ql2z3Q06DCptkiE0oobOYogpNccHD86O59NyCHWf7sk
2025-03-17 19:57:24,125 - DEBUG - Token decodificado correctamente, user_id: 1
2025-03-17 19:57:24,125 - DEBUG - Sesión configurada para el usuario: 1
2025-03-17 19:57:24,426 - DEBUG - Verificando permisos para el usuario: None
2025-03-17 19:57:24,426 - DEBUG - Usuario no autenticado: session.get('user_id') devolvió None
2025-03-17 19:57:24,755 - DEBUG - Verificando permisos para el usuario: None
2025-03-17 19:57:24,755 - DEBUG - Usuario no autenticado: session.get('user_id') devolvió None
2025-03-17 19:57:24,757 - DEBUG - Verificando permisos para el usuario: None
2025-03-17 19:57:24,757 - DEBUG - Usuario no autenticado: session.get('user_id') devolvió None
2025-03-17 19:59:33,641 - INFO - 🔧 Backend Flask iniciado.
2025-03-17 19:59:48,191 - DEBUG - Intento de inicio de sesión: admin@shelly.local
2025-03-17 19:59:48,200 - DEBUG - Usuario encontrado en la base de datos
2025-03-17 19:59:48,543 - DEBUG - Contraseña correcta
2025-03-17 19:59:48,543 - DEBUG - Token generado: eyJhbGciOiJIUzI1NiIsInR5cCI6IkpXVCJ9.eyJ1c2VyX2lkIjoxfQ.Ql2z3Q06DCptkiE0oobOYogpNccHD86O59NyCHWf7sk
2025-03-17 19:59:48,894 - DEBUG - Ejecutando middleware require_login
2025-03-17 19:59:48,894 - DEBUG - Authorization header: Bearer eyJhbGciOiJIUzI1NiIsInR5cCI6IkpXVCJ9.eyJ1c2VyX2lkIjoxfQ.Ql2z3Q06DCptkiE0oobOYogpNccHD86O59NyCHWf7sk
2025-03-17 19:59:48,894 - DEBUG - Token recibido: eyJhbGciOiJIUzI1NiIsInR5cCI6IkpXVCJ9.eyJ1c2VyX2lkIjoxfQ.Ql2z3Q06DCptkiE0oobOYogpNccHD86O59NyCHWf7sk
2025-03-17 19:59:48,895 - DEBUG - Token decodificado correctamente, user_id: 1
2025-03-17 19:59:48,895 - DEBUG - Sesión configurada para el usuario: 1
2025-03-17 19:59:49,203 - DEBUG - Verificando permisos para el usuario: None
2025-03-17 19:59:49,204 - DEBUG - Usuario no autenticado: session.get('user_id') devolvió None
2025-03-17 19:59:49,746 - DEBUG - Verificando permisos para el usuario: None
2025-03-17 19:59:49,747 - DEBUG - Usuario no autenticado: session.get('user_id') devolvió None
2025-03-17 19:59:49,887 - DEBUG - Verificando permisos para el usuario: None
2025-03-17 19:59:49,887 - DEBUG - Usuario no autenticado: session.get('user_id') devolvió None
2025-03-17 20:06:05,597 - INFO - 🔧 Backend Flask iniciado.
2025-03-17 20:06:35,078 - DEBUG - Intento de inicio de sesión: admin@shelly.local
2025-03-17 20:06:35,087 - DEBUG - Usuario encontrado en la base de datos
2025-03-17 20:06:35,427 - DEBUG - Contraseña correcta
2025-03-17 20:06:35,427 - DEBUG - Token generado: eyJhbGciOiJIUzI1NiIsInR5cCI6IkpXVCJ9.eyJ1c2VyX2lkIjoxfQ.Ql2z3Q06DCptkiE0oobOYogpNccHD86O59NyCHWf7sk
2025-03-17 20:06:35,714 - DEBUG - Ejecutando middleware require_login
2025-03-17 20:06:35,714 - DEBUG - Authorization header: Bearer eyJhbGciOiJIUzI1NiIsInR5cCI6IkpXVCJ9.eyJ1c2VyX2lkIjoxfQ.Ql2z3Q06DCptkiE0oobOYogpNccHD86O59NyCHWf7sk
2025-03-17 20:06:35,714 - DEBUG - Token recibido: eyJhbGciOiJIUzI1NiIsInR5cCI6IkpXVCJ9.eyJ1c2VyX2lkIjoxfQ.Ql2z3Q06DCptkiE0oobOYogpNccHD86O59NyCHWf7sk
2025-03-17 20:06:35,714 - DEBUG - Token decodificado correctamente, user_id: 1
2025-03-17 20:06:35,714 - DEBUG - Sesión configurada para el usuario: 1
2025-03-17 20:06:36,015 - DEBUG - Verificando permisos para el usuario: None
2025-03-17 20:06:36,015 - DEBUG - Usuario no autenticado: session.get('user_id') devolvió None
2025-03-17 20:06:36,468 - DEBUG - Verificando permisos para el usuario: None
2025-03-17 20:06:36,468 - DEBUG - Usuario no autenticado: session.get('user_id') devolvió None
2025-03-17 20:06:36,609 - DEBUG - Verificando permisos para el usuario: None
2025-03-17 20:06:36,609 - DEBUG - Usuario no autenticado: session.get('user_id') devolvió None
2025-03-17 20:22:34,355 - INFO - 🔧 Backend Flask iniciado.
2025-03-17 20:22:53,916 - DEBUG - Intento de inicio de sesión: admin@shelly.local
2025-03-17 20:22:53,925 - DEBUG - Usuario encontrado en la base de datos
2025-03-17 20:22:54,265 - DEBUG - Contraseña correcta
2025-03-17 20:22:54,265 - DEBUG - Token generado: eyJhbGciOiJIUzI1NiIsInR5cCI6IkpXVCJ9.eyJ1c2VyX2lkIjoxfQ.Ql2z3Q06DCptkiE0oobOYogpNccHD86O59NyCHWf7sk
2025-03-17 20:22:54,596 - DEBUG - Ejecutando middleware require_login
2025-03-17 20:22:54,596 - DEBUG - Authorization header: Bearer eyJhbGciOiJIUzI1NiIsInR5cCI6IkpXVCJ9.eyJ1c2VyX2lkIjoxfQ.Ql2z3Q06DCptkiE0oobOYogpNccHD86O59NyCHWf7sk
2025-03-17 20:22:54,596 - DEBUG - Token recibido: eyJhbGciOiJIUzI1NiIsInR5cCI6IkpXVCJ9.eyJ1c2VyX2lkIjoxfQ.Ql2z3Q06DCptkiE0oobOYogpNccHD86O59NyCHWf7sk
2025-03-17 20:22:54,596 - DEBUG - Token decodificado correctamente, user_id: 1
2025-03-17 20:22:54,596 - DEBUG - Estado actual de la sesión antes de configurar: <FileSystemSession {}>
2025-03-17 20:22:54,597 - DEBUG - Estado de la sesión después de configurar: <FileSystemSession {'user_id': 1, 'logged_in': True}>
2025-03-17 20:22:54,597 - DEBUG - Sesión configurada para el usuario: 1
2025-03-17 20:22:54,902 - DEBUG - Verificando permisos para el usuario: None
2025-03-17 20:22:54,902 - DEBUG - Usuario no autenticado: session.get('user_id') devolvió None
2025-03-17 20:22:55,220 - DEBUG - Verificando permisos para el usuario: None
2025-03-17 20:22:55,220 - DEBUG - Usuario no autenticado: session.get('user_id') devolvió None
2025-03-17 20:22:55,222 - DEBUG - Verificando permisos para el usuario: None
2025-03-17 20:22:55,222 - DEBUG - Usuario no autenticado: session.get('user_id') devolvió None
2025-03-17 20:25:47,467 - INFO - 🔧 Backend Flask iniciado.
2025-03-17 20:26:03,918 - DEBUG - Intento de inicio de sesión: admin@shelly.local
2025-03-17 20:26:03,928 - DEBUG - Usuario encontrado en la base de datos
2025-03-17 20:26:04,271 - DEBUG - Contraseña correcta
2025-03-17 20:26:04,271 - DEBUG - Token generado: eyJhbGciOiJIUzI1NiIsInR5cCI6IkpXVCJ9.eyJ1c2VyX2lkIjoxfQ.Ql2z3Q06DCptkiE0oobOYogpNccHD86O59NyCHWf7sk
2025-03-17 20:26:04,632 - DEBUG - Ejecutando middleware require_login
2025-03-17 20:26:04,632 - DEBUG - Authorization header: Bearer eyJhbGciOiJIUzI1NiIsInR5cCI6IkpXVCJ9.eyJ1c2VyX2lkIjoxfQ.Ql2z3Q06DCptkiE0oobOYogpNccHD86O59NyCHWf7sk
2025-03-17 20:26:04,632 - DEBUG - Token recibido: eyJhbGciOiJIUzI1NiIsInR5cCI6IkpXVCJ9.eyJ1c2VyX2lkIjoxfQ.Ql2z3Q06DCptkiE0oobOYogpNccHD86O59NyCHWf7sk
2025-03-17 20:26:04,632 - DEBUG - Token decodificado correctamente, user_id: 1
2025-03-17 20:26:04,632 - DEBUG - Estado actual de la sesión antes de configurar: <FileSystemSession {}>
2025-03-17 20:26:04,633 - DEBUG - Estado de la sesión después de configurar: <FileSystemSession {'user_id': 1, 'logged_in': True}>
2025-03-17 20:26:04,633 - DEBUG - Sesión configurada para el usuario: 1
2025-03-17 20:26:05,047 - DEBUG - Verificando permisos para el usuario: None
2025-03-17 20:26:05,047 - DEBUG - Estado actual de la sesión: <FileSystemSession {}>
2025-03-17 20:26:05,048 - DEBUG - Usuario no autenticado: session.get('user_id') devolvió None
2025-03-17 20:26:05,508 - DEBUG - Verificando permisos para el usuario: None
2025-03-17 20:26:05,519 - DEBUG - Estado actual de la sesión: <FileSystemSession {}>
2025-03-17 20:26:05,519 - DEBUG - Usuario no autenticado: session.get('user_id') devolvió None
2025-03-17 20:26:05,658 - DEBUG - Verificando permisos para el usuario: None
2025-03-17 20:26:05,658 - DEBUG - Estado actual de la sesión: <FileSystemSession {}>
2025-03-17 20:26:05,658 - DEBUG - Usuario no autenticado: session.get('user_id') devolvió None
2025-03-17 20:41:26,884 - INFO - 🔧 Backend Flask iniciado.
2025-03-17 20:41:41,377 - DEBUG - Estado de la sesión al inicio de la solicitud: <FileSystemSession {}>
2025-03-17 20:41:41,378 - DEBUG - Estado de la sesión al final de la solicitud: <FileSystemSession {}>
2025-03-17 20:41:41,649 - DEBUG - Estado de la sesión al inicio de la solicitud: <FileSystemSession {}>
2025-03-17 20:41:41,650 - DEBUG - Intento de inicio de sesión: admin@shelly.local
2025-03-17 20:41:41,658 - DEBUG - Usuario encontrado en la base de datos
2025-03-17 20:41:41,996 - DEBUG - Contraseña correcta
2025-03-17 20:41:41,996 - DEBUG - Token generado: eyJhbGciOiJIUzI1NiIsInR5cCI6IkpXVCJ9.eyJ1c2VyX2lkIjoxfQ.Ql2z3Q06DCptkiE0oobOYogpNccHD86O59NyCHWf7sk
2025-03-17 20:41:41,996 - DEBUG - Estado de la sesión al final de la solicitud: <FileSystemSession {'user_id': 1, 'logged_in': True}>
2025-03-17 20:41:42,205 - DEBUG - Estado de la sesión al inicio de la solicitud: <FileSystemSession {}>
2025-03-17 20:41:42,206 - DEBUG - Estado de la sesión al final de la solicitud: <FileSystemSession {}>
2025-03-17 20:41:42,452 - DEBUG - Estado de la sesión al inicio de la solicitud: <FileSystemSession {}>
2025-03-17 20:41:42,452 - DEBUG - Ejecutando middleware require_login
2025-03-17 20:41:42,452 - DEBUG - Authorization header: Bearer eyJhbGciOiJIUzI1NiIsInR5cCI6IkpXVCJ9.eyJ1c2VyX2lkIjoxfQ.Ql2z3Q06DCptkiE0oobOYogpNccHD86O59NyCHWf7sk
2025-03-17 20:41:42,452 - DEBUG - Token recibido: eyJhbGciOiJIUzI1NiIsInR5cCI6IkpXVCJ9.eyJ1c2VyX2lkIjoxfQ.Ql2z3Q06DCptkiE0oobOYogpNccHD86O59NyCHWf7sk
2025-03-17 20:41:42,453 - DEBUG - Token decodificado correctamente, user_id: 1
2025-03-17 20:41:42,453 - DEBUG - Estado actual de la sesión antes de configurar: <FileSystemSession {}>
2025-03-17 20:41:42,453 - DEBUG - Estado de la sesión después de configurar: <FileSystemSession {'user_id': 1, 'logged_in': True}>
2025-03-17 20:41:42,453 - DEBUG - Sesión configurada para el usuario: 1
2025-03-17 20:41:42,453 - DEBUG - Estado de la sesión al final de la solicitud: <FileSystemSession {'user_id': 1, 'logged_in': True}>
2025-03-17 20:41:42,733 - DEBUG - Estado de la sesión al inicio de la solicitud: <FileSystemSession {}>
2025-03-17 20:41:42,733 - DEBUG - Estado de la sesión al final de la solicitud: <FileSystemSession {}>
2025-03-17 20:41:42,881 - DEBUG - Estado de la sesión al inicio de la solicitud: <FileSystemSession {}>
2025-03-17 20:41:42,881 - DEBUG - Verificando permisos para el usuario: None
2025-03-17 20:41:42,881 - DEBUG - Estado actual de la sesión: <FileSystemSession {}>
2025-03-17 20:41:42,881 - DEBUG - Usuario no autenticado: session.get('user_id') devolvió None
2025-03-17 20:41:42,882 - DEBUG - Estado de la sesión al final de la solicitud: <FileSystemSession {}>
2025-03-17 20:41:43,085 - DEBUG - Estado de la sesión al inicio de la solicitud: <FileSystemSession {}>
2025-03-17 20:41:43,085 - DEBUG - Estado de la sesión al final de la solicitud: <FileSystemSession {}>
2025-03-17 20:41:43,086 - DEBUG - Estado de la sesión al inicio de la solicitud: <FileSystemSession {}>
2025-03-17 20:41:43,087 - DEBUG - Estado de la sesión al final de la solicitud: <FileSystemSession {}>
2025-03-17 20:41:43,226 - DEBUG - Estado de la sesión al inicio de la solicitud: <FileSystemSession {}>
2025-03-17 20:41:43,226 - DEBUG - Verificando permisos para el usuario: None
2025-03-17 20:41:43,226 - DEBUG - Estado actual de la sesión: <FileSystemSession {}>
2025-03-17 20:41:43,226 - DEBUG - Usuario no autenticado: session.get('user_id') devolvió None
2025-03-17 20:41:43,226 - DEBUG - Estado de la sesión al final de la solicitud: <FileSystemSession {}>
2025-03-17 20:41:43,242 - DEBUG - Estado de la sesión al inicio de la solicitud: <FileSystemSession {}>
2025-03-17 20:41:43,242 - DEBUG - Verificando permisos para el usuario: None
2025-03-17 20:41:43,242 - DEBUG - Estado actual de la sesión: <FileSystemSession {}>
2025-03-17 20:41:43,242 - DEBUG - Usuario no autenticado: session.get('user_id') devolvió None
2025-03-17 20:41:43,243 - DEBUG - Estado de la sesión al final de la solicitud: <FileSystemSession {}>
2025-03-17 20:46:28,319 - DEBUG - Estado de la sesión al inicio de la solicitud: <FileSystemSession {}>
2025-03-17 20:46:28,319 - DEBUG - Estado de la sesión al final de la solicitud: <FileSystemSession {}>
2025-03-17 20:46:28,592 - DEBUG - Estado de la sesión al inicio de la solicitud: <FileSystemSession {}>
2025-03-17 20:46:28,593 - DEBUG - Intento de inicio de sesión: admin@shelly.local
2025-03-17 20:46:28,596 - DEBUG - Usuario encontrado en la base de datos
2025-03-17 20:46:28,935 - DEBUG - Contraseña correcta
2025-03-17 20:46:28,935 - DEBUG - Token generado: eyJhbGciOiJIUzI1NiIsInR5cCI6IkpXVCJ9.eyJ1c2VyX2lkIjoxfQ.Ql2z3Q06DCptkiE0oobOYogpNccHD86O59NyCHWf7sk
2025-03-17 20:46:28,935 - DEBUG - Estado de la sesión al final de la solicitud: <FileSystemSession {'user_id': 1, 'logged_in': True}>
2025-03-17 20:46:29,079 - DEBUG - Estado de la sesión al inicio de la solicitud: <FileSystemSession {}>
2025-03-17 20:46:29,080 - DEBUG - Estado de la sesión al final de la solicitud: <FileSystemSession {}>
2025-03-17 20:46:29,220 - DEBUG - Estado de la sesión al inicio de la solicitud: <FileSystemSession {}>
2025-03-17 20:46:29,220 - DEBUG - Ejecutando middleware require_login
2025-03-17 20:46:29,220 - DEBUG - Authorization header: Bearer eyJhbGciOiJIUzI1NiIsInR5cCI6IkpXVCJ9.eyJ1c2VyX2lkIjoxfQ.Ql2z3Q06DCptkiE0oobOYogpNccHD86O59NyCHWf7sk
2025-03-17 20:46:29,220 - DEBUG - Token recibido: eyJhbGciOiJIUzI1NiIsInR5cCI6IkpXVCJ9.eyJ1c2VyX2lkIjoxfQ.Ql2z3Q06DCptkiE0oobOYogpNccHD86O59NyCHWf7sk
2025-03-17 20:46:29,220 - DEBUG - Token decodificado correctamente, user_id: 1
2025-03-17 20:46:29,220 - DEBUG - Estado actual de la sesión antes de configurar: <FileSystemSession {}>
2025-03-17 20:46:29,221 - DEBUG - Estado de la sesión después de configurar: <FileSystemSession {'user_id': 1, 'logged_in': True}>
2025-03-17 20:46:29,221 - DEBUG - Sesión configurada para el usuario: 1
2025-03-17 20:46:29,221 - DEBUG - Estado de la sesión al final de la solicitud: <FileSystemSession {'user_id': 1, 'logged_in': True}>
2025-03-17 20:46:29,377 - DEBUG - Estado de la sesión al inicio de la solicitud: <FileSystemSession {}>
2025-03-17 20:46:29,377 - DEBUG - Estado de la sesión al final de la solicitud: <FileSystemSession {}>
2025-03-17 20:46:29,517 - DEBUG - Estado de la sesión al inicio de la solicitud: <FileSystemSession {}>
2025-03-17 20:46:29,517 - DEBUG - Verificando permisos para el usuario: None
2025-03-17 20:46:29,518 - DEBUG - Estado actual de la sesión: <FileSystemSession {}>
2025-03-17 20:46:29,518 - DEBUG - Usuario no autenticado: session.get('user_id') devolvió None
2025-03-17 20:46:29,518 - DEBUG - Estado de la sesión al final de la solicitud: <FileSystemSession {}>
2025-03-17 20:46:29,682 - DEBUG - Estado de la sesión al inicio de la solicitud: <FileSystemSession {}>
2025-03-17 20:46:29,683 - DEBUG - Estado de la sesión al final de la solicitud: <FileSystemSession {}>
2025-03-17 20:46:29,825 - DEBUG - Estado de la sesión al inicio de la solicitud: <FileSystemSession {}>
2025-03-17 20:46:29,825 - DEBUG - Estado de la sesión al final de la solicitud: <FileSystemSession {}>
2025-03-17 20:46:29,965 - DEBUG - Estado de la sesión al inicio de la solicitud: <FileSystemSession {}>
2025-03-17 20:46:29,965 - DEBUG - Verificando permisos para el usuario: None
2025-03-17 20:46:29,965 - DEBUG - Estado actual de la sesión: <FileSystemSession {}>
2025-03-17 20:46:29,965 - DEBUG - Usuario no autenticado: session.get('user_id') devolvió None
2025-03-17 20:46:29,966 - DEBUG - Estado de la sesión al final de la solicitud: <FileSystemSession {}>
2025-03-17 20:46:30,109 - DEBUG - Estado de la sesión al inicio de la solicitud: <FileSystemSession {}>
2025-03-17 20:46:30,110 - DEBUG - Verificando permisos para el usuario: None
2025-03-17 20:46:30,110 - DEBUG - Estado actual de la sesión: <FileSystemSession {}>
2025-03-17 20:46:30,110 - DEBUG - Usuario no autenticado: session.get('user_id') devolvió None
2025-03-17 20:46:30,110 - DEBUG - Estado de la sesión al final de la solicitud: <FileSystemSession {}>
2025-03-17 20:46:49,348 - DEBUG - Estado de la sesión al inicio de la solicitud: <FileSystemSession {}>
2025-03-17 20:46:49,348 - DEBUG - Estado de la sesión al final de la solicitud: <FileSystemSession {}>
2025-03-17 20:46:49,490 - DEBUG - Estado de la sesión al inicio de la solicitud: <FileSystemSession {}>
2025-03-17 20:46:49,490 - DEBUG - Intento de inicio de sesión: admin@shelly.local
2025-03-17 20:46:49,493 - DEBUG - Usuario encontrado en la base de datos
2025-03-17 20:46:49,833 - DEBUG - Contraseña correcta
2025-03-17 20:46:49,833 - DEBUG - Token generado: eyJhbGciOiJIUzI1NiIsInR5cCI6IkpXVCJ9.eyJ1c2VyX2lkIjoxfQ.Ql2z3Q06DCptkiE0oobOYogpNccHD86O59NyCHWf7sk
2025-03-17 20:46:49,833 - DEBUG - Estado de la sesión al final de la solicitud: <FileSystemSession {'user_id': 1, 'logged_in': True}>
2025-03-17 20:46:49,981 - DEBUG - Estado de la sesión al inicio de la solicitud: <FileSystemSession {}>
2025-03-17 20:46:49,981 - DEBUG - Estado de la sesión al final de la solicitud: <FileSystemSession {}>
2025-03-17 20:46:50,135 - DEBUG - Estado de la sesión al inicio de la solicitud: <FileSystemSession {}>
2025-03-17 20:46:50,136 - DEBUG - Ejecutando middleware require_login
2025-03-17 20:46:50,136 - DEBUG - Authorization header: Bearer eyJhbGciOiJIUzI1NiIsInR5cCI6IkpXVCJ9.eyJ1c2VyX2lkIjoxfQ.Ql2z3Q06DCptkiE0oobOYogpNccHD86O59NyCHWf7sk
2025-03-17 20:46:50,136 - DEBUG - Token recibido: eyJhbGciOiJIUzI1NiIsInR5cCI6IkpXVCJ9.eyJ1c2VyX2lkIjoxfQ.Ql2z3Q06DCptkiE0oobOYogpNccHD86O59NyCHWf7sk
2025-03-17 20:46:50,136 - DEBUG - Token decodificado correctamente, user_id: 1
2025-03-17 20:46:50,136 - DEBUG - Estado actual de la sesión antes de configurar: <FileSystemSession {}>
2025-03-17 20:46:50,136 - DEBUG - Estado de la sesión después de configurar: <FileSystemSession {'user_id': 1, 'logged_in': True}>
2025-03-17 20:46:50,136 - DEBUG - Sesión configurada para el usuario: 1
2025-03-17 20:46:50,136 - DEBUG - Estado de la sesión al final de la solicitud: <FileSystemSession {'user_id': 1, 'logged_in': True}>
2025-03-17 20:46:50,303 - DEBUG - Estado de la sesión al inicio de la solicitud: <FileSystemSession {}>
2025-03-17 20:46:50,303 - DEBUG - Estado de la sesión al final de la solicitud: <FileSystemSession {}>
2025-03-17 20:46:50,559 - DEBUG - Estado de la sesión al inicio de la solicitud: <FileSystemSession {}>
2025-03-17 20:46:50,559 - DEBUG - Verificando permisos para el usuario: None
2025-03-17 20:46:50,559 - DEBUG - Estado actual de la sesión: <FileSystemSession {}>
2025-03-17 20:46:50,559 - DEBUG - Usuario no autenticado: session.get('user_id') devolvió None
2025-03-17 20:46:50,559 - DEBUG - Estado de la sesión al final de la solicitud: <FileSystemSession {}>
2025-03-17 20:46:50,744 - DEBUG - Estado de la sesión al inicio de la solicitud: <FileSystemSession {}>
2025-03-17 20:46:50,744 - DEBUG - Estado de la sesión al final de la solicitud: <FileSystemSession {}>
2025-03-17 20:46:50,892 - DEBUG - Estado de la sesión al inicio de la solicitud: <FileSystemSession {}>
2025-03-17 20:46:50,892 - DEBUG - Estado de la sesión al final de la solicitud: <FileSystemSession {}>
2025-03-17 20:46:51,034 - DEBUG - Estado de la sesión al inicio de la solicitud: <FileSystemSession {}>
2025-03-17 20:46:51,034 - DEBUG - Verificando permisos para el usuario: None
2025-03-17 20:46:51,034 - DEBUG - Estado actual de la sesión: <FileSystemSession {}>
2025-03-17 20:46:51,034 - DEBUG - Usuario no autenticado: session.get('user_id') devolvió None
2025-03-17 20:46:51,034 - DEBUG - Estado de la sesión al final de la solicitud: <FileSystemSession {}>
2025-03-17 20:46:51,179 - DEBUG - Estado de la sesión al inicio de la solicitud: <FileSystemSession {}>
2025-03-17 20:46:51,179 - DEBUG - Verificando permisos para el usuario: None
2025-03-17 20:46:51,179 - DEBUG - Estado actual de la sesión: <FileSystemSession {}>
2025-03-17 20:46:51,179 - DEBUG - Usuario no autenticado: session.get('user_id') devolvió None
2025-03-17 20:46:51,179 - DEBUG - Estado de la sesión al final de la solicitud: <FileSystemSession {}>
